<?xml version="1.0" ?>
<!-- =================================================================================== -->
<!-- |    This document was autogenerated by xacro from ./src/tvmd/urdf/tvmd.xacro     | -->
<!-- |    EDITING THIS FILE BY HAND IS NOT RECOMMENDED                                 | -->
<!-- =================================================================================== -->
<robot name="tvmd">
  <material name="silver">
    <color rgba="0.700 0.700 0.700 1.000"/>
  </material>
  <material name="yellow">
    <color rgba="1.000 1.000 0.000 1.000"/>
  </material>
  <material name="black">
    <color rgba="0.000 0.000 0.000 1.000"/>
  </material>
  <material name="gray">
    <color rgba="0.200 0.200 0.200 1.000"/>
  </material>
  <material name="dark_blue">
    <color rgba="0.100 0.100 0.300 1.000"/>
  </material>
  <!-- <gazebo>
  <plugin name="control" filename="libgazebo_ros_control.so"/>
</gazebo> -->
  <!-- Dynamics -->
  <!-- IMU -->
  <gazebo reference="base_link">
    <sensor name="imu_sensor" type="imu">
      <always_on>true</always_on>
      <update_rate>250</update_rate>
    </sensor>
  </gazebo>
  <gazebo reference="base_link">
    <sensor name="air_pressure_sensor" type="air_pressure">
      <always_on>true</always_on>
      <update_rate>50</update_rate>
      <air_pressure>
        <pressure>
          <noise type="gaussian">
            <mean>0</mean>
            <stddev>0.01</stddev>
          </noise>
        </pressure>
      </air_pressure>
    </sensor>
  </gazebo>
  <!-- Define Module Macros -->
  <!-- Links -->
  <!-- Joints -->
  <!-- Define Robot -->
  <!-- Team System -->
  <link name="base_link">
    <inertial>
      <origin rpy="0 0 0" xyz="0.023872244589948865 -0.0009500409901555752 0.03522161274068737"/>
      <mass value="2.83791501"/>
      <inertia ixx="0.01210074" ixy="0.00034820" ixz="-0.00023145" iyy="0.01841678" iyz="-0.00017235" izz="0.02144845"/>
    </inertial>
    <visual>
      <origin rpy="0 0 0" xyz="0 0 0"/>
      <geometry>
        <mesh filename="package://tvmd/meshes/navigator/NavigatorModule-Sim.stl" scale="0.001 0.001 0.001"/>
      </geometry>
      <material name="dark_blue"/>
    </visual>
    <collision>
      <origin rpy="0 0 0" xyz="0 0 0"/>
      <geometry>
        <mesh filename="package://tvmd/meshes/navigator/NavigatorModule-Sim.stl" scale="0.001 0.001 0.001"/>
      </geometry>
    </collision>
    <velocity_decay/>
  </link>
  <link name="module1_body_link">
    <inertial>
      <origin rpy="0 0 0" xyz="0.03950362887818236 0.0002336451659535331 -0.03359920964595942"/>
      <mass value="0.50885294"/>
      <inertia ixx="0.00286197" ixy="0.00001218" ixz="-0.00038649" iyy="0.01669981" iyz="-0.00000803" izz="0.01760490"/>
    </inertial>
    <visual>
      <origin rpy="0 0 0" xyz="0 0 0"/>
      <geometry>
        <mesh filename="package://tvmd/meshes/agent/base_link.stl" scale="0.001 0.001 0.001"/>
      </geometry>
      <material name="black"/>
    </visual>
    <!-- <collision>
      <origin xyz="0 0 0" rpy="0 0 0"/>
      <geometry>
        <mesh filename="package://tvmd/meshes/agent/base_link.stl" scale="0.001 0.001 0.001"/>
      </geometry>
    </collision> -->
    <velocity_decay/>
  </link>
  <gazebo reference="module1_body_link">
    <material>Gazebo/Black</material>
    <!-- Frictions -->
    <mu1>0.2</mu1>
    <mu2>0.2</mu2>
    <selfCollide>false</selfCollide>
    <gravity>true</gravity>
  </gazebo>
  <link name="module1_gimbal_link">
    <inertial>
      <origin rpy="0 0 0" xyz="0.1843065553329719 0.00019186033306794898 -0.0008717237920348236"/>
      <mass value="0.03395528"/>
      <inertia ixx="0.00000159" ixy="0.0" ixz="0.0" iyy="0.00031944" iyz="-0.00000003" izz="0.00031947"/>
    </inertial>
    <visual>
      <origin rpy="0 0 0" xyz="0.201475 -0.0 0.0"/>
      <geometry>
        <mesh filename="package://tvmd/meshes/agent/Gimbal_Frame_1.stl" scale="0.001 0.001 0.001"/>
      </geometry>
      <material name="gray"/>
    </visual>
    <!-- <collision>
      <origin xyz="0.201475 -0.0 0.0" rpy="0 0 0"/>
      <geometry>
        <mesh filename="package://tvmd/meshes/agent/Gimbal_Frame_1.stl" scale="0.001 0.001 0.001"/>
      </geometry>
    </collision> -->
  </link>
  <gazebo reference="module1_gimbal_link">
    <material>Gazebo/Gray</material>
    <!-- Frictions -->
    <mu1>0.2</mu1>
    <mu2>0.2</mu2>
    <selfCollide>false</selfCollide>
    <gravity>true</gravity>
  </gazebo>
  <link name="module1_actuator_link">
    <inertial>
      <origin rpy="0 0 0" xyz="8.674536786092266e-05 -0.012737509954264759 -0.0036057781438169905"/>
      <mass value="0.12541538"/>
      <inertia ixx="0.00030455" ixy="-0.00000010" ixz="-0.00000018" iyy="0.00029933" iyz="0.00000437" izz="0.00001545"/>
    </inertial>
    <visual>
      <origin rpy="0 0 0" xyz="-0.0005 -0.011 0.0"/>
      <geometry>
        <mesh filename="package://tvmd/meshes/agent/Actuator_1.stl" scale="0.001 0.001 0.001"/>
      </geometry>
      <material name="gray"/>
    </visual>
    <!-- <collision>
      <origin xyz="-0.0005 -0.011 0.0" rpy="0 0 0"/>
      <geometry>
        <mesh filename="package://tvmd/meshes/agent/Actuator_1.stl" scale="0.001 0.001 0.001"/>
      </geometry>
    </collision> -->
  </link>
  <gazebo reference="module1_actuator_link">
    <material>Gazebo/Gray</material>
    <!-- Frictions -->
    <mu1>0.2</mu1>
    <mu2>0.2</mu2>
    <selfCollide>false</selfCollide>
    <gravity>true</gravity>
  </gazebo>
  <link name="module1_prop1_link">
    <inertial>
      <origin rpy="0 0 0" xyz="3.216065230847529e-08 -3.6756938827939636e-08 -0.003327345566246087"/>
      <mass value="0.00253778"/>
      <inertia ixx="0.00000005" ixy="0.0" ixz="-0.00000009" iyy="0.00000705" iyz="0.0" izz="0.00000702"/>
    </inertial>
    <visual>
      <origin rpy="0 0 0" xyz="-0.0005 -0.0005 -0.0816"/>
      <geometry>
        <mesh filename="package://tvmd/meshes/agent/propeller_9047_1.stl" scale="0.001 0.001 0.001"/>
      </geometry>
      <material name="yellow"/>
    </visual>
    <!-- <collision>
      <origin xyz="-0.0005 -0.0005 -0.0816" rpy="0 0 0"/>
      <geometry>
        <mesh filename="package://tvmd/meshes/agent/propeller_9047_1.stl" scale="0.001 0.001 0.001"/>
      </geometry>
    </collision> -->
  </link>
  <gazebo reference="module1_prop1_link">
    <material>Gazebo/Yellow</material>
    <!-- Frictions -->
    <mu1>0.2</mu1>
    <mu2>0.2</mu2>
    <selfCollide>false</selfCollide>
    <gravity>true</gravity>
  </gazebo>
  <link name="module1_prop2_link">
    <inertial>
      <origin rpy="0 0 0" xyz="3.216065230847529e-08 -3.6756938827939636e-08 -0.003327345566246087"/>
      <mass value="0.00253778"/>
      <inertia ixx="0.00000005" ixy="0.0" ixz="-0.00000009" iyy="0.00000705" iyz="0.0" izz="0.00000702"/>
    </inertial>
    <visual>
      <origin rpy="0 0 0" xyz="-0.001 -0.0 0.0746"/>
      <geometry>
        <mesh filename="package://tvmd/meshes/agent/propeller_9047_2.stl" scale="0.001 0.001 0.001"/>
      </geometry>
      <material name="yellow"/>
    </visual>
    <!-- <collision>
      <origin xyz="-0.001 -0.0 0.0746" rpy="0 0 0"/>
      <geometry>
        <mesh filename="package://tvmd/meshes/agent/propeller_9047_2.stl" scale="0.001 0.001 0.001"/>
      </geometry>
    </collision> -->
  </link>
  <gazebo reference="module1_prop2_link">
    <material>Gazebo/Yellow</material>
    <!-- Frictions -->
    <mu1>0.2</mu1>
    <mu2>0.2</mu2>
    <selfCollide>false</selfCollide>
    <gravity>true</gravity>
  </gazebo>
  <joint name="module1_body_gimbal_joint" type="revolute">
    <origin rpy="0 0 0" xyz="-0.201475 0.0 0.0"/>
    <parent link="module1_body_link"/>
    <child link="module1_gimbal_link"/>
    <axis xyz="-1.0 0.0 0.0"/>
    <limit effort="30000" lower="-1.5707963267948966" upper="1.5707963267948966" velocity="10.0"/>
    <dynamics damping="1.000"/>
    <physics>
      <ode implicit_spring_damper="1"/>
    </physics>
  </joint>
  <transmission name="revolute_module1_body_gimbal_joint">
    <type>transmission_interface/SimpleTransmission</type>
    <joint name="module1_body_gimbal_joint">
      <hardwareInterface>hardware_interface/EffortJointInterface</hardwareInterface>
    </joint>
    <actuator name="actuator_module1_body_gimbal_joint">
      <hardwareInterface>hardware_interface/EffortJointInterface</hardwareInterface>
      <mechanicalReduction>1</mechanicalReduction>
    </actuator>
  </transmission>
  <gazebo>
    <plugin filename="gz-sim-joint-position-controller-system" name="gz::sim::systems::JointPositionController">
      <joint_name>module1_body_gimbal_joint</joint_name>
      <sub_topic>servo_0</sub_topic>
      <!-- <topic>"/model/tvmd_0/servo_${joint_index}"</topic> -->
      <!-- <joint_index>"${joint_index}"</joint_index> -->
    </plugin>
  </gazebo>
  <joint name="module1_gimbal_actuator_joint" type="revolute">
    <origin rpy="0 0 0" xyz="0.201975 0.011 0.0"/>
    <parent link="module1_gimbal_link"/>
    <child link="module1_actuator_link"/>
    <axis xyz="0.0 -1.0 -0.0"/>
    <limit effort="30000" lower="-0.5235987755982988" upper="0.5235987755982988" velocity="10.0"/>
    <dynamics damping="1.000"/>
    <physics>
      <ode implicit_spring_damper="1"/>
    </physics>
  </joint>
  <transmission name="revolute_module1_gimbal_actuator_joint">
    <type>transmission_interface/SimpleTransmission</type>
    <joint name="module1_gimbal_actuator_joint">
      <hardwareInterface>hardware_interface/EffortJointInterface</hardwareInterface>
    </joint>
    <actuator name="actuator_module1_gimbal_actuator_joint">
      <hardwareInterface>hardware_interface/EffortJointInterface</hardwareInterface>
      <mechanicalReduction>1</mechanicalReduction>
    </actuator>
  </transmission>
  <gazebo>
    <plugin filename="gz-sim-joint-position-controller-system" name="gz::sim::systems::JointPositionController">
      <joint_name>module1_gimbal_actuator_joint</joint_name>
      <sub_topic>servo_1</sub_topic>
      <!-- <topic>"/model/tvmd_0/servo_${joint_index}"</topic> -->
      <!-- <joint_index>"${joint_index}"</joint_index> -->
    </plugin>
  </gazebo>
  <joint name="module1_actuator_prop1_joint" type="continuous">
    <origin rpy="0 0 0" xyz="0.0 -0.0105 0.0816"/>
    <parent link="module1_actuator_link"/>
    <child link="module1_prop1_link"/>
    <axis xyz="-0.0 -0.0 -1.0"/>
    <limit effort="30000" lower="-1e+16" upper="1e+16" velocity="10000.0"/>
    <!-- <limit lower="-1e+16" upper="1e+16" /> -->
  </joint>
  <transmission name="revolute_module1_actuator_prop1_joint">
    <type>transmission_interface/SimpleTransmission</type>
    <joint name="module1_actuator_prop1_joint">
      <hardwareInterface>hardware_interface/EffortJointInterface</hardwareInterface>
    </joint>
    <actuator name="actuator_module1_actuator_prop1_joint">
      <hardwareInterface>hardware_interface/EffortJointInterface</hardwareInterface>
      <mechanicalReduction>1</mechanicalReduction>
    </actuator>
  </transmission>
  <gazebo>
    <plugin filename="gz-sim-multicopter-motor-model-system" name="gz::sim::systems::MulticopterMotorModel">
      <jointName>module1_actuator_prop1_joint</jointName>
      <linkName>module1_prop1_link</linkName>
      <turningDirection>ccw</turningDirection>
      <timeConstantUp>0.0125</timeConstantUp>
      <timeConstantDown>0.025</timeConstantDown>
      <maxRotVelocity>1500</maxRotVelocity>
      <motorConstant>2e-05</motorConstant>
      <momentConstant>0.06</momentConstant>
      <commandSubTopic>command/motor_speed</commandSubTopic>
      <motorNumber>0</motorNumber>
      <rotorDragCoefficient>0.000106428</rotorDragCoefficient>
      <rollingMomentCoefficient>1e-06</rollingMomentCoefficient>
      <rotorVelocitySlowdownSim>20</rotorVelocitySlowdownSim>
      <motorType>velocity</motorType>
    </plugin>
  </gazebo>
  <joint name="module1_actuator_prop2_joint" type="continuous">
    <origin rpy="0 0 0" xyz="0.0005 -0.011 -0.0746"/>
    <parent link="module1_actuator_link"/>
    <child link="module1_prop2_link"/>
    <axis xyz="0.0 0.0 1.0"/>
    <limit effort="30000" lower="-1e+16" upper="1e+16" velocity="10000.0"/>
    <!-- <limit lower="-1e+16" upper="1e+16" /> -->
  </joint>
  <transmission name="revolute_module1_actuator_prop2_joint">
    <type>transmission_interface/SimpleTransmission</type>
    <joint name="module1_actuator_prop2_joint">
      <hardwareInterface>hardware_interface/EffortJointInterface</hardwareInterface>
    </joint>
    <actuator name="actuator_module1_actuator_prop2_joint">
      <hardwareInterface>hardware_interface/EffortJointInterface</hardwareInterface>
      <mechanicalReduction>1</mechanicalReduction>
    </actuator>
  </transmission>
  <gazebo>
    <plugin filename="gz-sim-multicopter-motor-model-system" name="gz::sim::systems::MulticopterMotorModel">
      <jointName>module1_actuator_prop2_joint</jointName>
      <linkName>module1_prop2_link</linkName>
      <turningDirection>ccw</turningDirection>
      <timeConstantUp>0.0125</timeConstantUp>
      <timeConstantDown>0.025</timeConstantDown>
      <maxRotVelocity>1500</maxRotVelocity>
      <motorConstant>2e-05</motorConstant>
      <momentConstant>0.06</momentConstant>
      <commandSubTopic>command/motor_speed</commandSubTopic>
      <motorNumber>1</motorNumber>
      <rotorDragCoefficient>0.000106428</rotorDragCoefficient>
      <rollingMomentCoefficient>1e-06</rollingMomentCoefficient>
      <rotorVelocitySlowdownSim>20</rotorVelocitySlowdownSim>
      <motorType>velocity</motorType>
    </plugin>
  </gazebo>
  <link name="module2_body_link">
    <inertial>
      <origin rpy="0 0 0" xyz="0.03950362887818236 0.0002336451659535331 -0.03359920964595942"/>
      <mass value="0.50885294"/>
      <inertia ixx="0.00286197" ixy="0.00001218" ixz="-0.00038649" iyy="0.01669981" iyz="-0.00000803" izz="0.01760490"/>
    </inertial>
    <visual>
      <origin rpy="0 0 0" xyz="0 0 0"/>
      <geometry>
        <mesh filename="package://tvmd/meshes/agent/base_link.stl" scale="0.001 0.001 0.001"/>
      </geometry>
      <material name="black"/>
    </visual>
    <!-- <collision>
      <origin xyz="0 0 0" rpy="0 0 0"/>
      <geometry>
        <mesh filename="package://tvmd/meshes/agent/base_link.stl" scale="0.001 0.001 0.001"/>
      </geometry>
    </collision> -->
    <velocity_decay/>
  </link>
  <gazebo reference="module2_body_link">
    <material>Gazebo/Black</material>
    <!-- Frictions -->
    <mu1>0.2</mu1>
    <mu2>0.2</mu2>
    <selfCollide>false</selfCollide>
    <gravity>true</gravity>
  </gazebo>
  <link name="module2_gimbal_link">
    <inertial>
      <origin rpy="0 0 0" xyz="0.1843065553329719 0.00019186033306794898 -0.0008717237920348236"/>
      <mass value="0.03395528"/>
      <inertia ixx="0.00000159" ixy="0.0" ixz="0.0" iyy="0.00031944" iyz="-0.00000003" izz="0.00031947"/>
    </inertial>
    <visual>
      <origin rpy="0 0 0" xyz="0.201475 -0.0 0.0"/>
      <geometry>
        <mesh filename="package://tvmd/meshes/agent/Gimbal_Frame_1.stl" scale="0.001 0.001 0.001"/>
      </geometry>
      <material name="gray"/>
    </visual>
    <!-- <collision>
      <origin xyz="0.201475 -0.0 0.0" rpy="0 0 0"/>
      <geometry>
        <mesh filename="package://tvmd/meshes/agent/Gimbal_Frame_1.stl" scale="0.001 0.001 0.001"/>
      </geometry>
    </collision> -->
  </link>
  <gazebo reference="module2_gimbal_link">
    <material>Gazebo/Gray</material>
    <!-- Frictions -->
    <mu1>0.2</mu1>
    <mu2>0.2</mu2>
    <selfCollide>false</selfCollide>
    <gravity>true</gravity>
  </gazebo>
  <link name="module2_actuator_link">
    <inertial>
      <origin rpy="0 0 0" xyz="8.674536786092266e-05 -0.012737509954264759 -0.0036057781438169905"/>
      <mass value="0.12541538"/>
      <inertia ixx="0.00030455" ixy="-0.00000010" ixz="-0.00000018" iyy="0.00029933" iyz="0.00000437" izz="0.00001545"/>
    </inertial>
    <visual>
      <origin rpy="0 0 0" xyz="-0.0005 -0.011 0.0"/>
      <geometry>
        <mesh filename="package://tvmd/meshes/agent/Actuator_1.stl" scale="0.001 0.001 0.001"/>
      </geometry>
      <material name="gray"/>
    </visual>
    <!-- <collision>
      <origin xyz="-0.0005 -0.011 0.0" rpy="0 0 0"/>
      <geometry>
        <mesh filename="package://tvmd/meshes/agent/Actuator_1.stl" scale="0.001 0.001 0.001"/>
      </geometry>
    </collision> -->
  </link>
  <gazebo reference="module2_actuator_link">
    <material>Gazebo/Gray</material>
    <!-- Frictions -->
    <mu1>0.2</mu1>
    <mu2>0.2</mu2>
    <selfCollide>false</selfCollide>
    <gravity>true</gravity>
  </gazebo>
  <link name="module2_prop1_link">
    <inertial>
      <origin rpy="0 0 0" xyz="3.216065230847529e-08 -3.6756938827939636e-08 -0.003327345566246087"/>
      <mass value="0.00253778"/>
      <inertia ixx="0.00000005" ixy="0.0" ixz="-0.00000009" iyy="0.00000705" iyz="0.0" izz="0.00000702"/>
    </inertial>
    <visual>
      <origin rpy="0 0 0" xyz="-0.0005 -0.0005 -0.0816"/>
      <geometry>
        <mesh filename="package://tvmd/meshes/agent/propeller_9047_1.stl" scale="0.001 0.001 0.001"/>
      </geometry>
      <material name="yellow"/>
    </visual>
    <!-- <collision>
      <origin xyz="-0.0005 -0.0005 -0.0816" rpy="0 0 0"/>
      <geometry>
        <mesh filename="package://tvmd/meshes/agent/propeller_9047_1.stl" scale="0.001 0.001 0.001"/>
      </geometry>
    </collision> -->
  </link>
  <gazebo reference="module2_prop1_link">
    <material>Gazebo/Yellow</material>
    <!-- Frictions -->
    <mu1>0.2</mu1>
    <mu2>0.2</mu2>
    <selfCollide>false</selfCollide>
    <gravity>true</gravity>
  </gazebo>
  <link name="module2_prop2_link">
    <inertial>
      <origin rpy="0 0 0" xyz="3.216065230847529e-08 -3.6756938827939636e-08 -0.003327345566246087"/>
      <mass value="0.00253778"/>
      <inertia ixx="0.00000005" ixy="0.0" ixz="-0.00000009" iyy="0.00000705" iyz="0.0" izz="0.00000702"/>
    </inertial>
    <visual>
      <origin rpy="0 0 0" xyz="-0.001 -0.0 0.0746"/>
      <geometry>
        <mesh filename="package://tvmd/meshes/agent/propeller_9047_2.stl" scale="0.001 0.001 0.001"/>
      </geometry>
      <material name="yellow"/>
    </visual>
    <!-- <collision>
      <origin xyz="-0.001 -0.0 0.0746" rpy="0 0 0"/>
      <geometry>
        <mesh filename="package://tvmd/meshes/agent/propeller_9047_2.stl" scale="0.001 0.001 0.001"/>
      </geometry>
    </collision> -->
  </link>
  <gazebo reference="module2_prop2_link">
    <material>Gazebo/Yellow</material>
    <!-- Frictions -->
    <mu1>0.2</mu1>
    <mu2>0.2</mu2>
    <selfCollide>false</selfCollide>
    <gravity>true</gravity>
  </gazebo>
  <joint name="module2_body_gimbal_joint" type="revolute">
    <origin rpy="0 0 0" xyz="-0.201475 0.0 0.0"/>
    <parent link="module2_body_link"/>
    <child link="module2_gimbal_link"/>
    <axis xyz="-1.0 0.0 0.0"/>
    <limit effort="30000" lower="-1.5707963267948966" upper="1.5707963267948966" velocity="10.0"/>
    <dynamics damping="1.000"/>
    <physics>
      <ode implicit_spring_damper="1"/>
    </physics>
  </joint>
  <transmission name="revolute_module2_body_gimbal_joint">
    <type>transmission_interface/SimpleTransmission</type>
    <joint name="module2_body_gimbal_joint">
      <hardwareInterface>hardware_interface/EffortJointInterface</hardwareInterface>
    </joint>
    <actuator name="actuator_module2_body_gimbal_joint">
      <hardwareInterface>hardware_interface/EffortJointInterface</hardwareInterface>
      <mechanicalReduction>1</mechanicalReduction>
    </actuator>
  </transmission>
  <gazebo>
    <plugin filename="gz-sim-joint-position-controller-system" name="gz::sim::systems::JointPositionController">
      <joint_name>module2_body_gimbal_joint</joint_name>
      <sub_topic>servo_2</sub_topic>
      <!-- <topic>"/model/tvmd_0/servo_${joint_index}"</topic> -->
      <!-- <joint_index>"${joint_index}"</joint_index> -->
    </plugin>
  </gazebo>
  <joint name="module2_gimbal_actuator_joint" type="revolute">
    <origin rpy="0 0 0" xyz="0.201975 0.011 0.0"/>
    <parent link="module2_gimbal_link"/>
    <child link="module2_actuator_link"/>
    <axis xyz="0.0 -1.0 -0.0"/>
    <limit effort="30000" lower="-0.5235987755982988" upper="0.5235987755982988" velocity="10.0"/>
    <dynamics damping="1.000"/>
    <physics>
      <ode implicit_spring_damper="1"/>
    </physics>
  </joint>
  <transmission name="revolute_module2_gimbal_actuator_joint">
    <type>transmission_interface/SimpleTransmission</type>
    <joint name="module2_gimbal_actuator_joint">
      <hardwareInterface>hardware_interface/EffortJointInterface</hardwareInterface>
    </joint>
    <actuator name="actuator_module2_gimbal_actuator_joint">
      <hardwareInterface>hardware_interface/EffortJointInterface</hardwareInterface>
      <mechanicalReduction>1</mechanicalReduction>
    </actuator>
  </transmission>
  <gazebo>
    <plugin filename="gz-sim-joint-position-controller-system" name="gz::sim::systems::JointPositionController">
      <joint_name>module2_gimbal_actuator_joint</joint_name>
      <sub_topic>servo_3</sub_topic>
      <!-- <topic>"/model/tvmd_0/servo_${joint_index}"</topic> -->
      <!-- <joint_index>"${joint_index}"</joint_index> -->
    </plugin>
  </gazebo>
  <joint name="module2_actuator_prop1_joint" type="continuous">
    <origin rpy="0 0 0" xyz="0.0 -0.0105 0.0816"/>
    <parent link="module2_actuator_link"/>
    <child link="module2_prop1_link"/>
    <axis xyz="-0.0 -0.0 -1.0"/>
    <limit effort="30000" lower="-1e+16" upper="1e+16" velocity="10000.0"/>
    <!-- <limit lower="-1e+16" upper="1e+16" /> -->
  </joint>
  <transmission name="revolute_module2_actuator_prop1_joint">
    <type>transmission_interface/SimpleTransmission</type>
    <joint name="module2_actuator_prop1_joint">
      <hardwareInterface>hardware_interface/EffortJointInterface</hardwareInterface>
    </joint>
    <actuator name="actuator_module2_actuator_prop1_joint">
      <hardwareInterface>hardware_interface/EffortJointInterface</hardwareInterface>
      <mechanicalReduction>1</mechanicalReduction>
    </actuator>
  </transmission>
  <gazebo>
    <plugin filename="gz-sim-multicopter-motor-model-system" name="gz::sim::systems::MulticopterMotorModel">
      <jointName>module2_actuator_prop1_joint</jointName>
      <linkName>module2_prop1_link</linkName>
      <turningDirection>ccw</turningDirection>
      <timeConstantUp>0.0125</timeConstantUp>
      <timeConstantDown>0.025</timeConstantDown>
      <maxRotVelocity>1500</maxRotVelocity>
      <motorConstant>2e-05</motorConstant>
      <momentConstant>0.06</momentConstant>
      <commandSubTopic>command/motor_speed</commandSubTopic>
      <motorNumber>2</motorNumber>
      <rotorDragCoefficient>0.000106428</rotorDragCoefficient>
      <rollingMomentCoefficient>1e-06</rollingMomentCoefficient>
      <rotorVelocitySlowdownSim>20</rotorVelocitySlowdownSim>
      <motorType>velocity</motorType>
    </plugin>
  </gazebo>
  <joint name="module2_actuator_prop2_joint" type="continuous">
    <origin rpy="0 0 0" xyz="0.0005 -0.011 -0.0746"/>
    <parent link="module2_actuator_link"/>
    <child link="module2_prop2_link"/>
    <axis xyz="0.0 0.0 1.0"/>
    <limit effort="30000" lower="-1e+16" upper="1e+16" velocity="10000.0"/>
    <!-- <limit lower="-1e+16" upper="1e+16" /> -->
  </joint>
  <transmission name="revolute_module2_actuator_prop2_joint">
    <type>transmission_interface/SimpleTransmission</type>
    <joint name="module2_actuator_prop2_joint">
      <hardwareInterface>hardware_interface/EffortJointInterface</hardwareInterface>
    </joint>
    <actuator name="actuator_module2_actuator_prop2_joint">
      <hardwareInterface>hardware_interface/EffortJointInterface</hardwareInterface>
      <mechanicalReduction>1</mechanicalReduction>
    </actuator>
  </transmission>
  <gazebo>
    <plugin filename="gz-sim-multicopter-motor-model-system" name="gz::sim::systems::MulticopterMotorModel">
      <jointName>module2_actuator_prop2_joint</jointName>
      <linkName>module2_prop2_link</linkName>
      <turningDirection>ccw</turningDirection>
      <timeConstantUp>0.0125</timeConstantUp>
      <timeConstantDown>0.025</timeConstantDown>
      <maxRotVelocity>1500</maxRotVelocity>
      <motorConstant>2e-05</motorConstant>
      <momentConstant>0.06</momentConstant>
      <commandSubTopic>command/motor_speed</commandSubTopic>
      <motorNumber>3</motorNumber>
      <rotorDragCoefficient>0.000106428</rotorDragCoefficient>
      <rollingMomentCoefficient>1e-06</rollingMomentCoefficient>
      <rotorVelocitySlowdownSim>20</rotorVelocitySlowdownSim>
      <motorType>velocity</motorType>
    </plugin>
  </gazebo>
  <link name="module3_body_link">
    <inertial>
      <origin rpy="0 0 0" xyz="0.03950362887818236 0.0002336451659535331 -0.03359920964595942"/>
      <mass value="0.50885294"/>
      <inertia ixx="0.00286197" ixy="0.00001218" ixz="-0.00038649" iyy="0.01669981" iyz="-0.00000803" izz="0.01760490"/>
    </inertial>
    <visual>
      <origin rpy="0 0 0" xyz="0 0 0"/>
      <geometry>
        <mesh filename="package://tvmd/meshes/agent/base_link.stl" scale="0.001 0.001 0.001"/>
      </geometry>
      <material name="black"/>
    </visual>
    <!-- <collision>
      <origin xyz="0 0 0" rpy="0 0 0"/>
      <geometry>
        <mesh filename="package://tvmd/meshes/agent/base_link.stl" scale="0.001 0.001 0.001"/>
      </geometry>
    </collision> -->
    <velocity_decay/>
  </link>
  <gazebo reference="module3_body_link">
    <material>Gazebo/Black</material>
    <!-- Frictions -->
    <mu1>0.2</mu1>
    <mu2>0.2</mu2>
    <selfCollide>false</selfCollide>
    <gravity>true</gravity>
  </gazebo>
  <link name="module3_gimbal_link">
    <inertial>
      <origin rpy="0 0 0" xyz="0.1843065553329719 0.00019186033306794898 -0.0008717237920348236"/>
      <mass value="0.03395528"/>
      <inertia ixx="0.00000159" ixy="0.0" ixz="0.0" iyy="0.00031944" iyz="-0.00000003" izz="0.00031947"/>
    </inertial>
    <visual>
      <origin rpy="0 0 0" xyz="0.201475 -0.0 0.0"/>
      <geometry>
        <mesh filename="package://tvmd/meshes/agent/Gimbal_Frame_1.stl" scale="0.001 0.001 0.001"/>
      </geometry>
      <material name="gray"/>
    </visual>
    <!-- <collision>
      <origin xyz="0.201475 -0.0 0.0" rpy="0 0 0"/>
      <geometry>
        <mesh filename="package://tvmd/meshes/agent/Gimbal_Frame_1.stl" scale="0.001 0.001 0.001"/>
      </geometry>
    </collision> -->
  </link>
  <gazebo reference="module3_gimbal_link">
    <material>Gazebo/Gray</material>
    <!-- Frictions -->
    <mu1>0.2</mu1>
    <mu2>0.2</mu2>
    <selfCollide>false</selfCollide>
    <gravity>true</gravity>
  </gazebo>
  <link name="module3_actuator_link">
    <inertial>
      <origin rpy="0 0 0" xyz="8.674536786092266e-05 -0.012737509954264759 -0.0036057781438169905"/>
      <mass value="0.12541538"/>
      <inertia ixx="0.00030455" ixy="-0.00000010" ixz="-0.00000018" iyy="0.00029933" iyz="0.00000437" izz="0.00001545"/>
    </inertial>
    <visual>
      <origin rpy="0 0 0" xyz="-0.0005 -0.011 0.0"/>
      <geometry>
        <mesh filename="package://tvmd/meshes/agent/Actuator_1.stl" scale="0.001 0.001 0.001"/>
      </geometry>
      <material name="gray"/>
    </visual>
    <!-- <collision>
      <origin xyz="-0.0005 -0.011 0.0" rpy="0 0 0"/>
      <geometry>
        <mesh filename="package://tvmd/meshes/agent/Actuator_1.stl" scale="0.001 0.001 0.001"/>
      </geometry>
    </collision> -->
  </link>
  <gazebo reference="module3_actuator_link">
    <material>Gazebo/Gray</material>
    <!-- Frictions -->
    <mu1>0.2</mu1>
    <mu2>0.2</mu2>
    <selfCollide>false</selfCollide>
    <gravity>true</gravity>
  </gazebo>
  <link name="module3_prop1_link">
    <inertial>
      <origin rpy="0 0 0" xyz="3.216065230847529e-08 -3.6756938827939636e-08 -0.003327345566246087"/>
      <mass value="0.00253778"/>
      <inertia ixx="0.00000005" ixy="0.0" ixz="-0.00000009" iyy="0.00000705" iyz="0.0" izz="0.00000702"/>
    </inertial>
    <visual>
      <origin rpy="0 0 0" xyz="-0.0005 -0.0005 -0.0816"/>
      <geometry>
        <mesh filename="package://tvmd/meshes/agent/propeller_9047_1.stl" scale="0.001 0.001 0.001"/>
      </geometry>
      <material name="yellow"/>
    </visual>
    <!-- <collision>
      <origin xyz="-0.0005 -0.0005 -0.0816" rpy="0 0 0"/>
      <geometry>
        <mesh filename="package://tvmd/meshes/agent/propeller_9047_1.stl" scale="0.001 0.001 0.001"/>
      </geometry>
    </collision> -->
  </link>
  <gazebo reference="module3_prop1_link">
    <material>Gazebo/Yellow</material>
    <!-- Frictions -->
    <mu1>0.2</mu1>
    <mu2>0.2</mu2>
    <selfCollide>false</selfCollide>
    <gravity>true</gravity>
  </gazebo>
  <link name="module3_prop2_link">
    <inertial>
      <origin rpy="0 0 0" xyz="3.216065230847529e-08 -3.6756938827939636e-08 -0.003327345566246087"/>
      <mass value="0.00253778"/>
      <inertia ixx="0.00000005" ixy="0.0" ixz="-0.00000009" iyy="0.00000705" iyz="0.0" izz="0.00000702"/>
    </inertial>
    <visual>
      <origin rpy="0 0 0" xyz="-0.001 -0.0 0.0746"/>
      <geometry>
        <mesh filename="package://tvmd/meshes/agent/propeller_9047_2.stl" scale="0.001 0.001 0.001"/>
      </geometry>
      <material name="yellow"/>
    </visual>
    <!-- <collision>
      <origin xyz="-0.001 -0.0 0.0746" rpy="0 0 0"/>
      <geometry>
        <mesh filename="package://tvmd/meshes/agent/propeller_9047_2.stl" scale="0.001 0.001 0.001"/>
      </geometry>
    </collision> -->
  </link>
  <gazebo reference="module3_prop2_link">
    <material>Gazebo/Yellow</material>
    <!-- Frictions -->
    <mu1>0.2</mu1>
    <mu2>0.2</mu2>
    <selfCollide>false</selfCollide>
    <gravity>true</gravity>
  </gazebo>
  <joint name="module3_body_gimbal_joint" type="revolute">
    <origin rpy="0 0 0" xyz="-0.201475 0.0 0.0"/>
    <parent link="module3_body_link"/>
    <child link="module3_gimbal_link"/>
    <axis xyz="-1.0 0.0 0.0"/>
    <limit effort="30000" lower="-1.5707963267948966" upper="1.5707963267948966" velocity="10.0"/>
    <dynamics damping="1.000"/>
    <physics>
      <ode implicit_spring_damper="1"/>
    </physics>
  </joint>
  <transmission name="revolute_module3_body_gimbal_joint">
    <type>transmission_interface/SimpleTransmission</type>
    <joint name="module3_body_gimbal_joint">
      <hardwareInterface>hardware_interface/EffortJointInterface</hardwareInterface>
    </joint>
    <actuator name="actuator_module3_body_gimbal_joint">
      <hardwareInterface>hardware_interface/EffortJointInterface</hardwareInterface>
      <mechanicalReduction>1</mechanicalReduction>
    </actuator>
  </transmission>
  <gazebo>
    <plugin filename="gz-sim-joint-position-controller-system" name="gz::sim::systems::JointPositionController">
      <joint_name>module3_body_gimbal_joint</joint_name>
      <sub_topic>servo_4</sub_topic>
      <!-- <topic>"/model/tvmd_0/servo_${joint_index}"</topic> -->
      <!-- <joint_index>"${joint_index}"</joint_index> -->
    </plugin>
  </gazebo>
  <joint name="module3_gimbal_actuator_joint" type="revolute">
    <origin rpy="0 0 0" xyz="0.201975 0.011 0.0"/>
    <parent link="module3_gimbal_link"/>
    <child link="module3_actuator_link"/>
    <axis xyz="0.0 -1.0 -0.0"/>
    <limit effort="30000" lower="-0.5235987755982988" upper="0.5235987755982988" velocity="10.0"/>
    <dynamics damping="1.000"/>
    <physics>
      <ode implicit_spring_damper="1"/>
    </physics>
  </joint>
  <transmission name="revolute_module3_gimbal_actuator_joint">
    <type>transmission_interface/SimpleTransmission</type>
    <joint name="module3_gimbal_actuator_joint">
      <hardwareInterface>hardware_interface/EffortJointInterface</hardwareInterface>
    </joint>
    <actuator name="actuator_module3_gimbal_actuator_joint">
      <hardwareInterface>hardware_interface/EffortJointInterface</hardwareInterface>
      <mechanicalReduction>1</mechanicalReduction>
    </actuator>
  </transmission>
  <gazebo>
    <plugin filename="gz-sim-joint-position-controller-system" name="gz::sim::systems::JointPositionController">
      <joint_name>module3_gimbal_actuator_joint</joint_name>
      <sub_topic>servo_5</sub_topic>
      <!-- <topic>"/model/tvmd_0/servo_${joint_index}"</topic> -->
      <!-- <joint_index>"${joint_index}"</joint_index> -->
    </plugin>
  </gazebo>
  <joint name="module3_actuator_prop1_joint" type="continuous">
    <origin rpy="0 0 0" xyz="0.0 -0.0105 0.0816"/>
    <parent link="module3_actuator_link"/>
    <child link="module3_prop1_link"/>
    <axis xyz="-0.0 -0.0 -1.0"/>
    <limit effort="30000" lower="-1e+16" upper="1e+16" velocity="10000.0"/>
    <!-- <limit lower="-1e+16" upper="1e+16" /> -->
  </joint>
  <transmission name="revolute_module3_actuator_prop1_joint">
    <type>transmission_interface/SimpleTransmission</type>
    <joint name="module3_actuator_prop1_joint">
      <hardwareInterface>hardware_interface/EffortJointInterface</hardwareInterface>
    </joint>
    <actuator name="actuator_module3_actuator_prop1_joint">
      <hardwareInterface>hardware_interface/EffortJointInterface</hardwareInterface>
      <mechanicalReduction>1</mechanicalReduction>
    </actuator>
  </transmission>
  <gazebo>
    <plugin filename="gz-sim-multicopter-motor-model-system" name="gz::sim::systems::MulticopterMotorModel">
      <jointName>module3_actuator_prop1_joint</jointName>
      <linkName>module3_prop1_link</linkName>
      <turningDirection>ccw</turningDirection>
      <timeConstantUp>0.0125</timeConstantUp>
      <timeConstantDown>0.025</timeConstantDown>
      <maxRotVelocity>1500</maxRotVelocity>
      <motorConstant>2e-05</motorConstant>
      <momentConstant>0.06</momentConstant>
      <commandSubTopic>command/motor_speed</commandSubTopic>
      <motorNumber>4</motorNumber>
      <rotorDragCoefficient>0.000106428</rotorDragCoefficient>
      <rollingMomentCoefficient>1e-06</rollingMomentCoefficient>
      <rotorVelocitySlowdownSim>20</rotorVelocitySlowdownSim>
      <motorType>velocity</motorType>
    </plugin>
  </gazebo>
  <joint name="module3_actuator_prop2_joint" type="continuous">
    <origin rpy="0 0 0" xyz="0.0005 -0.011 -0.0746"/>
    <parent link="module3_actuator_link"/>
    <child link="module3_prop2_link"/>
    <axis xyz="0.0 0.0 1.0"/>
    <limit effort="30000" lower="-1e+16" upper="1e+16" velocity="10000.0"/>
    <!-- <limit lower="-1e+16" upper="1e+16" /> -->
  </joint>
  <transmission name="revolute_module3_actuator_prop2_joint">
    <type>transmission_interface/SimpleTransmission</type>
    <joint name="module3_actuator_prop2_joint">
      <hardwareInterface>hardware_interface/EffortJointInterface</hardwareInterface>
    </joint>
    <actuator name="actuator_module3_actuator_prop2_joint">
      <hardwareInterface>hardware_interface/EffortJointInterface</hardwareInterface>
      <mechanicalReduction>1</mechanicalReduction>
    </actuator>
  </transmission>
  <gazebo>
    <plugin filename="gz-sim-multicopter-motor-model-system" name="gz::sim::systems::MulticopterMotorModel">
      <jointName>module3_actuator_prop2_joint</jointName>
      <linkName>module3_prop2_link</linkName>
      <turningDirection>ccw</turningDirection>
      <timeConstantUp>0.0125</timeConstantUp>
      <timeConstantDown>0.025</timeConstantDown>
      <maxRotVelocity>1500</maxRotVelocity>
      <motorConstant>2e-05</motorConstant>
      <momentConstant>0.06</momentConstant>
      <commandSubTopic>command/motor_speed</commandSubTopic>
      <motorNumber>5</motorNumber>
      <rotorDragCoefficient>0.000106428</rotorDragCoefficient>
      <rollingMomentCoefficient>1e-06</rollingMomentCoefficient>
      <rotorVelocitySlowdownSim>20</rotorVelocitySlowdownSim>
      <motorType>velocity</motorType>
    </plugin>
  </gazebo>
  <link name="module4_body_link">
    <inertial>
      <origin rpy="0 0 0" xyz="0.03950362887818236 0.0002336451659535331 -0.03359920964595942"/>
      <mass value="0.50885294"/>
      <inertia ixx="0.00286197" ixy="0.00001218" ixz="-0.00038649" iyy="0.01669981" iyz="-0.00000803" izz="0.01760490"/>
    </inertial>
    <visual>
      <origin rpy="0 0 0" xyz="0 0 0"/>
      <geometry>
        <mesh filename="package://tvmd/meshes/agent/base_link.stl" scale="0.001 0.001 0.001"/>
      </geometry>
      <material name="black"/>
    </visual>
    <!-- <collision>
      <origin xyz="0 0 0" rpy="0 0 0"/>
      <geometry>
        <mesh filename="package://tvmd/meshes/agent/base_link.stl" scale="0.001 0.001 0.001"/>
      </geometry>
    </collision> -->
    <velocity_decay/>
  </link>
  <gazebo reference="module4_body_link">
    <material>Gazebo/Black</material>
    <!-- Frictions -->
    <mu1>0.2</mu1>
    <mu2>0.2</mu2>
    <selfCollide>false</selfCollide>
    <gravity>true</gravity>
  </gazebo>
  <link name="module4_gimbal_link">
    <inertial>
      <origin rpy="0 0 0" xyz="0.1843065553329719 0.00019186033306794898 -0.0008717237920348236"/>
      <mass value="0.03395528"/>
      <inertia ixx="0.00000159" ixy="0.0" ixz="0.0" iyy="0.00031944" iyz="-0.00000003" izz="0.00031947"/>
    </inertial>
    <visual>
      <origin rpy="0 0 0" xyz="0.201475 -0.0 0.0"/>
      <geometry>
        <mesh filename="package://tvmd/meshes/agent/Gimbal_Frame_1.stl" scale="0.001 0.001 0.001"/>
      </geometry>
      <material name="gray"/>
    </visual>
    <!-- <collision>
      <origin xyz="0.201475 -0.0 0.0" rpy="0 0 0"/>
      <geometry>
        <mesh filename="package://tvmd/meshes/agent/Gimbal_Frame_1.stl" scale="0.001 0.001 0.001"/>
      </geometry>
    </collision> -->
  </link>
  <gazebo reference="module4_gimbal_link">
    <material>Gazebo/Gray</material>
    <!-- Frictions -->
    <mu1>0.2</mu1>
    <mu2>0.2</mu2>
    <selfCollide>false</selfCollide>
    <gravity>true</gravity>
  </gazebo>
  <link name="module4_actuator_link">
    <inertial>
      <origin rpy="0 0 0" xyz="8.674536786092266e-05 -0.012737509954264759 -0.0036057781438169905"/>
      <mass value="0.12541538"/>
      <inertia ixx="0.00030455" ixy="-0.00000010" ixz="-0.00000018" iyy="0.00029933" iyz="0.00000437" izz="0.00001545"/>
    </inertial>
    <visual>
      <origin rpy="0 0 0" xyz="-0.0005 -0.011 0.0"/>
      <geometry>
        <mesh filename="package://tvmd/meshes/agent/Actuator_1.stl" scale="0.001 0.001 0.001"/>
      </geometry>
      <material name="gray"/>
    </visual>
    <!-- <collision>
      <origin xyz="-0.0005 -0.011 0.0" rpy="0 0 0"/>
      <geometry>
        <mesh filename="package://tvmd/meshes/agent/Actuator_1.stl" scale="0.001 0.001 0.001"/>
      </geometry>
    </collision> -->
  </link>
  <gazebo reference="module4_actuator_link">
    <material>Gazebo/Gray</material>
    <!-- Frictions -->
    <mu1>0.2</mu1>
    <mu2>0.2</mu2>
    <selfCollide>false</selfCollide>
    <gravity>true</gravity>
  </gazebo>
  <link name="module4_prop1_link">
    <inertial>
      <origin rpy="0 0 0" xyz="3.216065230847529e-08 -3.6756938827939636e-08 -0.003327345566246087"/>
      <mass value="0.00253778"/>
      <inertia ixx="0.00000005" ixy="0.0" ixz="-0.00000009" iyy="0.00000705" iyz="0.0" izz="0.00000702"/>
    </inertial>
    <visual>
      <origin rpy="0 0 0" xyz="-0.0005 -0.0005 -0.0816"/>
      <geometry>
        <mesh filename="package://tvmd/meshes/agent/propeller_9047_1.stl" scale="0.001 0.001 0.001"/>
      </geometry>
      <material name="yellow"/>
    </visual>
    <!-- <collision>
      <origin xyz="-0.0005 -0.0005 -0.0816" rpy="0 0 0"/>
      <geometry>
        <mesh filename="package://tvmd/meshes/agent/propeller_9047_1.stl" scale="0.001 0.001 0.001"/>
      </geometry>
    </collision> -->
  </link>
  <gazebo reference="module4_prop1_link">
    <material>Gazebo/Yellow</material>
    <!-- Frictions -->
    <mu1>0.2</mu1>
    <mu2>0.2</mu2>
    <selfCollide>false</selfCollide>
    <gravity>true</gravity>
  </gazebo>
  <link name="module4_prop2_link">
    <inertial>
      <origin rpy="0 0 0" xyz="3.216065230847529e-08 -3.6756938827939636e-08 -0.003327345566246087"/>
      <mass value="0.00253778"/>
      <inertia ixx="0.00000005" ixy="0.0" ixz="-0.00000009" iyy="0.00000705" iyz="0.0" izz="0.00000702"/>
    </inertial>
    <visual>
      <origin rpy="0 0 0" xyz="-0.001 -0.0 0.0746"/>
      <geometry>
        <mesh filename="package://tvmd/meshes/agent/propeller_9047_2.stl" scale="0.001 0.001 0.001"/>
      </geometry>
      <material name="yellow"/>
    </visual>
    <!-- <collision>
      <origin xyz="-0.001 -0.0 0.0746" rpy="0 0 0"/>
      <geometry>
        <mesh filename="package://tvmd/meshes/agent/propeller_9047_2.stl" scale="0.001 0.001 0.001"/>
      </geometry>
    </collision> -->
  </link>
  <gazebo reference="module4_prop2_link">
    <material>Gazebo/Yellow</material>
    <!-- Frictions -->
    <mu1>0.2</mu1>
    <mu2>0.2</mu2>
    <selfCollide>false</selfCollide>
    <gravity>true</gravity>
  </gazebo>
  <joint name="module4_body_gimbal_joint" type="revolute">
    <origin rpy="0 0 0" xyz="-0.201475 0.0 0.0"/>
    <parent link="module4_body_link"/>
    <child link="module4_gimbal_link"/>
    <axis xyz="-1.0 0.0 0.0"/>
    <limit effort="30000" lower="-1.5707963267948966" upper="1.5707963267948966" velocity="10.0"/>
    <dynamics damping="1.000"/>
    <physics>
      <ode implicit_spring_damper="1"/>
    </physics>
  </joint>
  <transmission name="revolute_module4_body_gimbal_joint">
    <type>transmission_interface/SimpleTransmission</type>
    <joint name="module4_body_gimbal_joint">
      <hardwareInterface>hardware_interface/EffortJointInterface</hardwareInterface>
    </joint>
    <actuator name="actuator_module4_body_gimbal_joint">
      <hardwareInterface>hardware_interface/EffortJointInterface</hardwareInterface>
      <mechanicalReduction>1</mechanicalReduction>
    </actuator>
  </transmission>
  <gazebo>
    <plugin filename="gz-sim-joint-position-controller-system" name="gz::sim::systems::JointPositionController">
      <joint_name>module4_body_gimbal_joint</joint_name>
      <sub_topic>servo_6</sub_topic>
      <!-- <topic>"/model/tvmd_0/servo_${joint_index}"</topic> -->
      <!-- <joint_index>"${joint_index}"</joint_index> -->
    </plugin>
  </gazebo>
  <joint name="module4_gimbal_actuator_joint" type="revolute">
    <origin rpy="0 0 0" xyz="0.201975 0.011 0.0"/>
    <parent link="module4_gimbal_link"/>
    <child link="module4_actuator_link"/>
    <axis xyz="0.0 -1.0 -0.0"/>
    <limit effort="30000" lower="-0.5235987755982988" upper="0.5235987755982988" velocity="10.0"/>
    <dynamics damping="1.000"/>
    <physics>
      <ode implicit_spring_damper="1"/>
    </physics>
  </joint>
  <transmission name="revolute_module4_gimbal_actuator_joint">
    <type>transmission_interface/SimpleTransmission</type>
    <joint name="module4_gimbal_actuator_joint">
      <hardwareInterface>hardware_interface/EffortJointInterface</hardwareInterface>
    </joint>
    <actuator name="actuator_module4_gimbal_actuator_joint">
      <hardwareInterface>hardware_interface/EffortJointInterface</hardwareInterface>
      <mechanicalReduction>1</mechanicalReduction>
    </actuator>
  </transmission>
  <gazebo>
    <plugin filename="gz-sim-joint-position-controller-system" name="gz::sim::systems::JointPositionController">
      <joint_name>module4_gimbal_actuator_joint</joint_name>
      <sub_topic>servo_7</sub_topic>
      <!-- <topic>"/model/tvmd_0/servo_${joint_index}"</topic> -->
      <!-- <joint_index>"${joint_index}"</joint_index> -->
    </plugin>
  </gazebo>
  <joint name="module4_actuator_prop1_joint" type="continuous">
    <origin rpy="0 0 0" xyz="0.0 -0.0105 0.0816"/>
    <parent link="module4_actuator_link"/>
    <child link="module4_prop1_link"/>
    <axis xyz="-0.0 -0.0 -1.0"/>
    <limit effort="30000" lower="-1e+16" upper="1e+16" velocity="10000.0"/>
    <!-- <limit lower="-1e+16" upper="1e+16" /> -->
  </joint>
  <transmission name="revolute_module4_actuator_prop1_joint">
    <type>transmission_interface/SimpleTransmission</type>
    <joint name="module4_actuator_prop1_joint">
      <hardwareInterface>hardware_interface/EffortJointInterface</hardwareInterface>
    </joint>
    <actuator name="actuator_module4_actuator_prop1_joint">
      <hardwareInterface>hardware_interface/EffortJointInterface</hardwareInterface>
      <mechanicalReduction>1</mechanicalReduction>
    </actuator>
  </transmission>
  <gazebo>
    <plugin filename="gz-sim-multicopter-motor-model-system" name="gz::sim::systems::MulticopterMotorModel">
      <jointName>module4_actuator_prop1_joint</jointName>
      <linkName>module4_prop1_link</linkName>
      <turningDirection>ccw</turningDirection>
      <timeConstantUp>0.0125</timeConstantUp>
      <timeConstantDown>0.025</timeConstantDown>
      <maxRotVelocity>1500</maxRotVelocity>
      <motorConstant>2e-05</motorConstant>
      <momentConstant>0.06</momentConstant>
      <commandSubTopic>command/motor_speed</commandSubTopic>
      <motorNumber>6</motorNumber>
      <rotorDragCoefficient>0.000106428</rotorDragCoefficient>
      <rollingMomentCoefficient>1e-06</rollingMomentCoefficient>
      <rotorVelocitySlowdownSim>20</rotorVelocitySlowdownSim>
      <motorType>velocity</motorType>
    </plugin>
  </gazebo>
  <joint name="module4_actuator_prop2_joint" type="continuous">
    <origin rpy="0 0 0" xyz="0.0005 -0.011 -0.0746"/>
    <parent link="module4_actuator_link"/>
    <child link="module4_prop2_link"/>
    <axis xyz="0.0 0.0 1.0"/>
    <limit effort="30000" lower="-1e+16" upper="1e+16" velocity="10000.0"/>
    <!-- <limit lower="-1e+16" upper="1e+16" /> -->
  </joint>
  <transmission name="revolute_module4_actuator_prop2_joint">
    <type>transmission_interface/SimpleTransmission</type>
    <joint name="module4_actuator_prop2_joint">
      <hardwareInterface>hardware_interface/EffortJointInterface</hardwareInterface>
    </joint>
    <actuator name="actuator_module4_actuator_prop2_joint">
      <hardwareInterface>hardware_interface/EffortJointInterface</hardwareInterface>
      <mechanicalReduction>1</mechanicalReduction>
    </actuator>
  </transmission>
  <gazebo>
    <plugin filename="gz-sim-multicopter-motor-model-system" name="gz::sim::systems::MulticopterMotorModel">
      <jointName>module4_actuator_prop2_joint</jointName>
      <linkName>module4_prop2_link</linkName>
      <turningDirection>ccw</turningDirection>
      <timeConstantUp>0.0125</timeConstantUp>
      <timeConstantDown>0.025</timeConstantDown>
      <maxRotVelocity>1500</maxRotVelocity>
      <motorConstant>2e-05</motorConstant>
      <momentConstant>0.06</momentConstant>
      <commandSubTopic>command/motor_speed</commandSubTopic>
      <motorNumber>7</motorNumber>
      <rotorDragCoefficient>0.000106428</rotorDragCoefficient>
      <rollingMomentCoefficient>1e-06</rollingMomentCoefficient>
      <rotorVelocitySlowdownSim>20</rotorVelocitySlowdownSim>
      <motorType>velocity</motorType>
    </plugin>
  </gazebo>
  <joint name="rigid_base_link_module1_body_link" type="fixed">
    <origin rpy="0 0 0" xyz="-0.215 -0.215 0.068"/>
    <parent link="base_link"/>
    <child link="module1_body_link"/>
  </joint>
  <joint name="rigid_base_link_module2_body_link" type="fixed">
    <origin rpy="0 0 0" xyz="-0.215 0.215 0.068"/>
    <parent link="base_link"/>
    <child link="module2_body_link"/>
  </joint>
  <joint name="rigid_base_link_module3_body_link" type="fixed">
    <origin rpy="0 0 0" xyz="0.215 -0.215 0.068"/>
    <parent link="base_link"/>
    <child link="module3_body_link"/>
  </joint>
  <joint name="rigid_base_link_module4_body_link" type="fixed">
    <origin rpy="0 0 0" xyz="0.215 0.215 0.068"/>
    <parent link="base_link"/>
    <child link="module4_body_link"/>
  </joint>
  <static>0</static>
</robot>

