<?xml version="1.0" ?>
<!-- =================================================================================== -->
<!-- |    This document was autogenerated by xacro from ./src/tvmd/urdf/tvmd.xacro     | -->
<!-- |    EDITING THIS FILE BY HAND IS NOT RECOMMENDED                                 | -->
<!-- =================================================================================== -->
<robot name="tvmd">
  <material name="silver">
    <color rgba="0.700 0.700 0.700 1.000"/>
  </material>
  <material name="yellow">
    <color rgba="1.000 1.000 0.000 1.000"/>
  </material>
  <material name="black">
    <color rgba="0.000 0.000 0.000 1.000"/>
  </material>
  <material name="gray">
    <color rgba="0.200 0.200 0.200 1.000"/>
  </material>
  <material name="dark_blue">
    <color rgba="0.100 0.100 0.300 1.000"/>
  </material>
  <!-- <gazebo>
  <plugin name="control" filename="libgazebo_ros_control.so"/>
</gazebo> -->
  <!-- Dynamics -->
  <!-- IMU -->
  <gazebo reference="imu_sensor_link">
    <sensor name="imu_sensor" type="imu">
      <always_on>true</always_on>
      <update_rate>250</update_rate>
      <visualize>true</visualize>
    </sensor>
  </gazebo>
  <gazebo reference="base_link">
    <sensor name="air_pressure_sensor" type="air_pressure">
      <always_on>true</always_on>
      <update_rate>50</update_rate>
      <air_pressure>
        <pressure>
          <noise type="gaussian">
            <mean>0</mean>
            <stddev>0.01</stddev>
          </noise>
        </pressure>
      </air_pressure>
    </sensor>
  </gazebo>
  <!-- Define Module Macros -->
  <!-- Links -->
  <!-- Joints -->
  <!-- Define Robot -->
  <!-- Team System -->
  <link name="base_link">
    <inertial>
      <origin rpy="0 0 0" xyz="0.023872244589948865 -0.0009500409901555752 0.03522161274068737"/>
      <mass value="2.83791501"/>
      <inertia ixx="0.01210074" ixy="0.00034820" ixz="-0.00023145" iyy="0.01841678" iyz="-0.00017235" izz="0.02144845"/>
    </inertial>
    <visual>
      <origin rpy="0 0 0" xyz="0 0 0"/>
      <geometry>
        <mesh filename="package://tvmd/meshes/navigator/NavigatorModule-Sim.stl" scale="0.001 0.001 0.001"/>
      </geometry>
      <material name="dark_blue"/>
    </visual>
    <collision>
      <origin rpy="0 0 0.7853981633974483" xyz="0 0 0.05"/>
      <geometry>
        <!-- <mesh filename="package://tvmd/meshes/navigator/NavigatorModule-Sim.stl" scale="0.001 0.001 0.001"/> -->
        <box size="0.3 0.3 0.1"/>
      </geometry>
    </collision>
    <velocity_decay/>
  </link>
  <link name="imu_sensor_link">
    <collision>
      <origin rpy="0 0 0" xyz="0 0 0"/>
      <geometry>
        <box size="0.02 0.02 0.02"/>
      </geometry>
    </collision>
    <visual>
      <origin rpy="0 0 0" xyz="0 0 0"/>
      <geometry>
        <box size="0.02 0.02 0.02"/>
      </geometry>
      <material name="gray"/>
    </visual>
    <inertial>
      <mass value="0.001"/>
      <origin rpy="0 0 0" xyz="0 0 0"/>
      <inertia ixx="0.00000015" ixy="0" ixz="0" iyy="0.00000015" iyz="0" izz="0.00000015"/>
    </inertial>
  </link>
  <joint name="imu_sensor_joint" type="fixed">
    <axis xyz="0 0 1"/>
    <origin rpy="0 0 0" xyz="0 0 0"/>
    <parent link="base_link"/>
    <child link="imu_sensor_link"/>
  </joint>
  <link name="module1_body_link">
    <inertial>
      <origin rpy="0 0 0" xyz="0.0 0.0 0.0"/>
      <mass value="0.50823179"/>
      <inertia ixx="0.01671968" ixy="-0.00001217" ixz="-0.00000326" iyy="0.00290137" iyz="-0.00003388" izz="0.01758533"/>
    </inertial>
    <visual>
      <origin rpy="0 0 0" xyz="0 0 0"/>
      <geometry>
        <mesh filename="package://tvmd/meshes/agent/base_link.stl" scale="0.001 0.001 0.001"/>
      </geometry>
      <material name="black"/>
    </visual>
    <!-- <collision>
      <origin xyz="0 0 0" rpy="0 0 0"/>
      <geometry>
        <mesh filename="package://tvmd/meshes/agent/base_link.stl" scale="0.001 0.001 0.001"/>
      </geometry>
    </collision> -->
    <velocity_decay/>
  </link>
  <gazebo reference="module1_body_link">
    <material>Gazebo/Black</material>
    <!-- Frictions -->
    <mu1>0.2</mu1>
    <mu2>0.2</mu2>
    <selfCollide>false</selfCollide>
    <gravity>true</gravity>
  </gazebo>
  <link name="module1_gimbal_link">
    <inertial>
      <origin rpy="0 0 0" xyz="0.0 0.0 0.0"/>
      <mass value="0.03395528"/>
      <inertia ixx="0.00034948" ixy="0.0" ixz="0.0" iyy="0.00000164" iyz="-0.00000002" izz="0.00034950"/>
    </inertial>
    <visual>
      <origin rpy="0 0 0" xyz="0.0 0.0 -0.068"/>
      <geometry>
        <mesh filename="package://tvmd/meshes/agent/Gimbal_Frame_1.stl" scale="0.001 0.001 0.001"/>
      </geometry>
      <material name="gray"/>
    </visual>
    <collision name="module1_actuator_collision">
      <origin rpy="1.5707963267948966 0 0" xyz="0 0 0"/>
      <geometry>
        <cylinder length="0.400" radius="0.010"/>
      </geometry>
    </collision>
  </link>
  <gazebo reference="module1_gimbal_link">
    <material>Gazebo/Gray</material>
    <!-- Frictions -->
    <mu1>0.2</mu1>
    <mu2>0.2</mu2>
    <selfCollide>false</selfCollide>
    <gravity>true</gravity>
  </gazebo>
  <link name="module1_actuator_link">
    <inertial>
      <origin rpy="0 0 0" xyz="0.0 0.0 0.0"/>
      <mass value="0.12540720"/>
      <inertia ixx="0.00029933" ixy="-0.00000011" ixz="-0.00000476" iyy="0.00030455" iyz="0.00000018" izz="0.00001575"/>
    </inertial>
    <visual>
      <origin rpy="0 0 0" xyz="0.0 0.0 -0.068"/>
      <geometry>
        <mesh filename="package://tvmd/meshes/agent/Actuator_1.stl" scale="0.001 0.001 0.001"/>
      </geometry>
      <material name="gray"/>
    </visual>
  </link>
  <gazebo reference="module1_actuator_link">
    <material>Gazebo/Gray</material>
    <!-- Frictions -->
    <mu1>0.2</mu1>
    <mu2>0.2</mu2>
    <selfCollide>false</selfCollide>
    <gravity>true</gravity>
  </gazebo>
  <link name="module1_prop1_link">
    <inertial>
      <origin rpy="0 0 0" xyz="0.0 0.0 0.0"/>
      <mass value="0.00253778"/>
      <inertia ixx="0.00000702" ixy="0.00000000" ixz="0.00000000" iyy="0.00000005" iyz="-0.00000009" izz="0.00000705"/>
    </inertial>
    <visual>
      <origin rpy="1.5707963267948966 0 0" xyz="0.0 0.0 0.0"/>
      <geometry>
        <mesh filename="package://tvmd/meshes/agent/Propeller_9047.stl" scale="0.001 0.001 0.001"/>
      </geometry>
      <material name="yellow"/>
    </visual>
    <collision name="module1_rotor_1_collision">
      <origin rpy="0 0 0" xyz="0 0 0"/>
      <geometry>
        <cylinder length="0.005" radius="0.12"/>
      </geometry>
    </collision>
  </link>
  <gazebo reference="module1_prop1_link">
    <material>Gazebo/Yellow</material>
    <!-- Frictions -->
    <mu1>0.2</mu1>
    <mu2>0.2</mu2>
    <selfCollide>false</selfCollide>
    <gravity>true</gravity>
  </gazebo>
  <link name="module1_prop2_link">
    <inertial>
      <origin rpy="0 0 0" xyz="0.0 0.0 0.0"/>
      <mass value="0.00253778"/>
      <inertia ixx="0.00000702" ixy="0.00000000" ixz="0.00000000" iyy="0.00000005" iyz="-0.00000009" izz="0.00000705"/>
    </inertial>
    <visual>
      <origin rpy="1.5707963267948966 0 0" xyz="0.0 0.0 0.0"/>
      <geometry>
        <mesh filename="package://tvmd/meshes/agent/Propeller_9047.stl" scale="0.001 0.001 0.001"/>
      </geometry>
      <material name="yellow"/>
    </visual>
    <collision name="module1_rotor_2_collision">
      <origin rpy="0 0 0" xyz="0 0 0"/>
      <geometry>
        <cylinder length="0.005" radius="0.12"/>
      </geometry>
    </collision>
  </link>
  <gazebo reference="module1_prop2_link">
    <material>Gazebo/Yellow</material>
    <!-- Frictions -->
    <mu1>0.2</mu1>
    <mu2>0.2</mu2>
    <selfCollide>false</selfCollide>
    <gravity>true</gravity>
  </gazebo>
  <joint name="module1_body_gimbal_joint" type="revolute">
    <origin rpy="0 0 0" xyz="0.0 0.0 0.068"/>
    <parent link="module1_body_link"/>
    <child link="module1_gimbal_link"/>
    <axis xyz="0.0 1.0 0.0"/>
    <limit effort="30000" lower="-1.5707963267948966" upper="1.5707963267948966" velocity="10.0"/>
    <dynamics damping="0.000"/>
    <physics>
      <ode implicit_spring_damper="0"/>
    </physics>
  </joint>
  <transmission name="revolute_module1_body_gimbal_joint">
    <type>transmission_interface/SimpleTransmission</type>
    <joint name="module1_body_gimbal_joint">
      <hardwareInterface>hardware_interface/EffortJointInterface</hardwareInterface>
    </joint>
    <actuator name="actuator_module1_body_gimbal_joint">
      <hardwareInterface>hardware_interface/EffortJointInterface</hardwareInterface>
      <mechanicalReduction>1</mechanicalReduction>
    </actuator>
  </transmission>
  <gazebo>
    <plugin filename="gz-sim-joint-position-controller-system" name="gz::sim::systems::JointPositionController">
      <joint_name>module1_body_gimbal_joint</joint_name>
      <sub_topic>servo_1</sub_topic>
      <!-- <topic>"/model/tvmd_0/servo_${joint_index}"</topic> -->
      <!-- <joint_index>"${joint_index}"</joint_index> -->
    </plugin>
  </gazebo>
  <joint name="module1_gimbal_actuator_joint" type="revolute">
    <origin rpy="0 0 0" xyz="0.0 0.0 0.0"/>
    <parent link="module1_gimbal_link"/>
    <child link="module1_actuator_link"/>
    <axis xyz="1.0 0.0 0.0"/>
    <limit effort="30000" lower="-0.5235987755982988" upper="0.5235987755982988" velocity="10.0"/>
    <dynamics damping="0.000"/>
    <physics>
      <ode implicit_spring_damper="0"/>
    </physics>
  </joint>
  <transmission name="revolute_module1_gimbal_actuator_joint">
    <type>transmission_interface/SimpleTransmission</type>
    <joint name="module1_gimbal_actuator_joint">
      <hardwareInterface>hardware_interface/EffortJointInterface</hardwareInterface>
    </joint>
    <actuator name="actuator_module1_gimbal_actuator_joint">
      <hardwareInterface>hardware_interface/EffortJointInterface</hardwareInterface>
      <mechanicalReduction>1</mechanicalReduction>
    </actuator>
  </transmission>
  <gazebo>
    <plugin filename="gz-sim-joint-position-controller-system" name="gz::sim::systems::JointPositionController">
      <joint_name>module1_gimbal_actuator_joint</joint_name>
      <sub_topic>servo_0</sub_topic>
      <!-- <topic>"/model/tvmd_0/servo_${joint_index}"</topic> -->
      <!-- <joint_index>"${joint_index}"</joint_index> -->
    </plugin>
  </gazebo>
  <joint name="module1_actuator_prop1_joint" type="continuous">
    <origin rpy="0 0 0" xyz="0.0 0.0 0.0781"/>
    <parent link="module1_actuator_link"/>
    <child link="module1_prop1_link"/>
    <axis xyz="0.0 0.0 1.0"/>
    <limit effort="30000" lower="-1e+16" upper="1e+16" velocity="10000.0"/>
    <!-- <limit lower="-1e+16" upper="1e+16" /> -->
  </joint>
  <transmission name="revolute_module1_actuator_prop1_joint">
    <type>transmission_interface/SimpleTransmission</type>
    <joint name="module1_actuator_prop1_joint">
      <hardwareInterface>hardware_interface/EffortJointInterface</hardwareInterface>
    </joint>
    <actuator name="actuator_module1_actuator_prop1_joint">
      <hardwareInterface>hardware_interface/EffortJointInterface</hardwareInterface>
      <mechanicalReduction>1</mechanicalReduction>
    </actuator>
  </transmission>
  <gazebo>
    <plugin filename="gz-sim-multicopter-motor-model-system" name="gz::sim::systems::MulticopterMotorModel">
      <jointName>module1_actuator_prop1_joint</jointName>
      <linkName>module1_prop1_link</linkName>
      <turningDirection>ccw</turningDirection>
      <timeConstantUp>0.0125</timeConstantUp>
      <timeConstantDown>0.025</timeConstantDown>
      <maxRotVelocity>1500</maxRotVelocity>
      <motorConstant>2e-05</motorConstant>
      <momentConstant>0.06</momentConstant>
      <commandSubTopic>command/motor_speed</commandSubTopic>
      <motorNumber>0</motorNumber>
      <rotorDragCoefficient>0.000106428</rotorDragCoefficient>
      <rollingMomentCoefficient>1e-06</rollingMomentCoefficient>
      <rotorVelocitySlowdownSim>20</rotorVelocitySlowdownSim>
      <motorType>velocity</motorType>
    </plugin>
  </gazebo>
  <joint name="module1_actuator_prop2_joint" type="continuous">
    <origin rpy="0 0 0" xyz="0.0 0.0 -0.0781"/>
    <parent link="module1_actuator_link"/>
    <child link="module1_prop2_link"/>
    <axis xyz="0.0 0.0 -1.0"/>
    <limit effort="30000" lower="-1e+16" upper="1e+16" velocity="10000.0"/>
    <!-- <limit lower="-1e+16" upper="1e+16" /> -->
  </joint>
  <transmission name="revolute_module1_actuator_prop2_joint">
    <type>transmission_interface/SimpleTransmission</type>
    <joint name="module1_actuator_prop2_joint">
      <hardwareInterface>hardware_interface/EffortJointInterface</hardwareInterface>
    </joint>
    <actuator name="actuator_module1_actuator_prop2_joint">
      <hardwareInterface>hardware_interface/EffortJointInterface</hardwareInterface>
      <mechanicalReduction>1</mechanicalReduction>
    </actuator>
  </transmission>
  <gazebo>
    <plugin filename="gz-sim-multicopter-motor-model-system" name="gz::sim::systems::MulticopterMotorModel">
      <jointName>module1_actuator_prop2_joint</jointName>
      <linkName>module1_prop2_link</linkName>
      <turningDirection>ccw</turningDirection>
      <timeConstantUp>0.0125</timeConstantUp>
      <timeConstantDown>0.025</timeConstantDown>
      <maxRotVelocity>1500</maxRotVelocity>
      <motorConstant>2e-05</motorConstant>
      <momentConstant>0.06</momentConstant>
      <commandSubTopic>command/motor_speed</commandSubTopic>
      <motorNumber>1</motorNumber>
      <rotorDragCoefficient>0.000106428</rotorDragCoefficient>
      <rollingMomentCoefficient>1e-06</rollingMomentCoefficient>
      <rotorVelocitySlowdownSim>20</rotorVelocitySlowdownSim>
      <motorType>velocity</motorType>
    </plugin>
  </gazebo>
  <link name="module2_body_link">
    <inertial>
      <origin rpy="0 0 0" xyz="0.0 0.0 0.0"/>
      <mass value="0.50823179"/>
      <inertia ixx="0.01671968" ixy="-0.00001217" ixz="-0.00000326" iyy="0.00290137" iyz="-0.00003388" izz="0.01758533"/>
    </inertial>
    <visual>
      <origin rpy="0 0 0" xyz="0 0 0"/>
      <geometry>
        <mesh filename="package://tvmd/meshes/agent/base_link.stl" scale="0.001 0.001 0.001"/>
      </geometry>
      <material name="black"/>
    </visual>
    <!-- <collision>
      <origin xyz="0 0 0" rpy="0 0 0"/>
      <geometry>
        <mesh filename="package://tvmd/meshes/agent/base_link.stl" scale="0.001 0.001 0.001"/>
      </geometry>
    </collision> -->
    <velocity_decay/>
  </link>
  <gazebo reference="module2_body_link">
    <material>Gazebo/Black</material>
    <!-- Frictions -->
    <mu1>0.2</mu1>
    <mu2>0.2</mu2>
    <selfCollide>false</selfCollide>
    <gravity>true</gravity>
  </gazebo>
  <link name="module2_gimbal_link">
    <inertial>
      <origin rpy="0 0 0" xyz="0.0 0.0 0.0"/>
      <mass value="0.03395528"/>
      <inertia ixx="0.00034948" ixy="0.0" ixz="0.0" iyy="0.00000164" iyz="-0.00000002" izz="0.00034950"/>
    </inertial>
    <visual>
      <origin rpy="0 0 0" xyz="0.0 0.0 -0.068"/>
      <geometry>
        <mesh filename="package://tvmd/meshes/agent/Gimbal_Frame_1.stl" scale="0.001 0.001 0.001"/>
      </geometry>
      <material name="gray"/>
    </visual>
    <collision name="module2_actuator_collision">
      <origin rpy="1.5707963267948966 0 0" xyz="0 0 0"/>
      <geometry>
        <cylinder length="0.400" radius="0.010"/>
      </geometry>
    </collision>
  </link>
  <gazebo reference="module2_gimbal_link">
    <material>Gazebo/Gray</material>
    <!-- Frictions -->
    <mu1>0.2</mu1>
    <mu2>0.2</mu2>
    <selfCollide>false</selfCollide>
    <gravity>true</gravity>
  </gazebo>
  <link name="module2_actuator_link">
    <inertial>
      <origin rpy="0 0 0" xyz="0.0 0.0 0.0"/>
      <mass value="0.12540720"/>
      <inertia ixx="0.00029933" ixy="-0.00000011" ixz="-0.00000476" iyy="0.00030455" iyz="0.00000018" izz="0.00001575"/>
    </inertial>
    <visual>
      <origin rpy="0 0 0" xyz="0.0 0.0 -0.068"/>
      <geometry>
        <mesh filename="package://tvmd/meshes/agent/Actuator_1.stl" scale="0.001 0.001 0.001"/>
      </geometry>
      <material name="gray"/>
    </visual>
  </link>
  <gazebo reference="module2_actuator_link">
    <material>Gazebo/Gray</material>
    <!-- Frictions -->
    <mu1>0.2</mu1>
    <mu2>0.2</mu2>
    <selfCollide>false</selfCollide>
    <gravity>true</gravity>
  </gazebo>
  <link name="module2_prop1_link">
    <inertial>
      <origin rpy="0 0 0" xyz="0.0 0.0 0.0"/>
      <mass value="0.00253778"/>
      <inertia ixx="0.00000702" ixy="0.00000000" ixz="0.00000000" iyy="0.00000005" iyz="-0.00000009" izz="0.00000705"/>
    </inertial>
    <visual>
      <origin rpy="1.5707963267948966 0 0" xyz="0.0 0.0 0.0"/>
      <geometry>
        <mesh filename="package://tvmd/meshes/agent/Propeller_9047.stl" scale="0.001 0.001 0.001"/>
      </geometry>
      <material name="yellow"/>
    </visual>
    <collision name="module2_rotor_1_collision">
      <origin rpy="0 0 0" xyz="0 0 0"/>
      <geometry>
        <cylinder length="0.005" radius="0.12"/>
      </geometry>
    </collision>
  </link>
  <gazebo reference="module2_prop1_link">
    <material>Gazebo/Yellow</material>
    <!-- Frictions -->
    <mu1>0.2</mu1>
    <mu2>0.2</mu2>
    <selfCollide>false</selfCollide>
    <gravity>true</gravity>
  </gazebo>
  <link name="module2_prop2_link">
    <inertial>
      <origin rpy="0 0 0" xyz="0.0 0.0 0.0"/>
      <mass value="0.00253778"/>
      <inertia ixx="0.00000702" ixy="0.00000000" ixz="0.00000000" iyy="0.00000005" iyz="-0.00000009" izz="0.00000705"/>
    </inertial>
    <visual>
      <origin rpy="1.5707963267948966 0 0" xyz="0.0 0.0 0.0"/>
      <geometry>
        <mesh filename="package://tvmd/meshes/agent/Propeller_9047.stl" scale="0.001 0.001 0.001"/>
      </geometry>
      <material name="yellow"/>
    </visual>
    <collision name="module2_rotor_2_collision">
      <origin rpy="0 0 0" xyz="0 0 0"/>
      <geometry>
        <cylinder length="0.005" radius="0.12"/>
      </geometry>
    </collision>
  </link>
  <gazebo reference="module2_prop2_link">
    <material>Gazebo/Yellow</material>
    <!-- Frictions -->
    <mu1>0.2</mu1>
    <mu2>0.2</mu2>
    <selfCollide>false</selfCollide>
    <gravity>true</gravity>
  </gazebo>
  <joint name="module2_body_gimbal_joint" type="revolute">
    <origin rpy="0 0 0" xyz="0.0 0.0 0.068"/>
    <parent link="module2_body_link"/>
    <child link="module2_gimbal_link"/>
    <axis xyz="0.0 1.0 0.0"/>
    <limit effort="30000" lower="-1.5707963267948966" upper="1.5707963267948966" velocity="10.0"/>
    <dynamics damping="0.000"/>
    <physics>
      <ode implicit_spring_damper="0"/>
    </physics>
  </joint>
  <transmission name="revolute_module2_body_gimbal_joint">
    <type>transmission_interface/SimpleTransmission</type>
    <joint name="module2_body_gimbal_joint">
      <hardwareInterface>hardware_interface/EffortJointInterface</hardwareInterface>
    </joint>
    <actuator name="actuator_module2_body_gimbal_joint">
      <hardwareInterface>hardware_interface/EffortJointInterface</hardwareInterface>
      <mechanicalReduction>1</mechanicalReduction>
    </actuator>
  </transmission>
  <gazebo>
    <plugin filename="gz-sim-joint-position-controller-system" name="gz::sim::systems::JointPositionController">
      <joint_name>module2_body_gimbal_joint</joint_name>
      <sub_topic>servo_3</sub_topic>
      <!-- <topic>"/model/tvmd_0/servo_${joint_index}"</topic> -->
      <!-- <joint_index>"${joint_index}"</joint_index> -->
    </plugin>
  </gazebo>
  <joint name="module2_gimbal_actuator_joint" type="revolute">
    <origin rpy="0 0 0" xyz="0.0 0.0 0.0"/>
    <parent link="module2_gimbal_link"/>
    <child link="module2_actuator_link"/>
    <axis xyz="1.0 0.0 0.0"/>
    <limit effort="30000" lower="-0.5235987755982988" upper="0.5235987755982988" velocity="10.0"/>
    <dynamics damping="0.000"/>
    <physics>
      <ode implicit_spring_damper="0"/>
    </physics>
  </joint>
  <transmission name="revolute_module2_gimbal_actuator_joint">
    <type>transmission_interface/SimpleTransmission</type>
    <joint name="module2_gimbal_actuator_joint">
      <hardwareInterface>hardware_interface/EffortJointInterface</hardwareInterface>
    </joint>
    <actuator name="actuator_module2_gimbal_actuator_joint">
      <hardwareInterface>hardware_interface/EffortJointInterface</hardwareInterface>
      <mechanicalReduction>1</mechanicalReduction>
    </actuator>
  </transmission>
  <gazebo>
    <plugin filename="gz-sim-joint-position-controller-system" name="gz::sim::systems::JointPositionController">
      <joint_name>module2_gimbal_actuator_joint</joint_name>
      <sub_topic>servo_2</sub_topic>
      <!-- <topic>"/model/tvmd_0/servo_${joint_index}"</topic> -->
      <!-- <joint_index>"${joint_index}"</joint_index> -->
    </plugin>
  </gazebo>
  <joint name="module2_actuator_prop1_joint" type="continuous">
    <origin rpy="0 0 0" xyz="0.0 0.0 0.0781"/>
    <parent link="module2_actuator_link"/>
    <child link="module2_prop1_link"/>
    <axis xyz="0.0 0.0 1.0"/>
    <limit effort="30000" lower="-1e+16" upper="1e+16" velocity="10000.0"/>
    <!-- <limit lower="-1e+16" upper="1e+16" /> -->
  </joint>
  <transmission name="revolute_module2_actuator_prop1_joint">
    <type>transmission_interface/SimpleTransmission</type>
    <joint name="module2_actuator_prop1_joint">
      <hardwareInterface>hardware_interface/EffortJointInterface</hardwareInterface>
    </joint>
    <actuator name="actuator_module2_actuator_prop1_joint">
      <hardwareInterface>hardware_interface/EffortJointInterface</hardwareInterface>
      <mechanicalReduction>1</mechanicalReduction>
    </actuator>
  </transmission>
  <gazebo>
    <plugin filename="gz-sim-multicopter-motor-model-system" name="gz::sim::systems::MulticopterMotorModel">
      <jointName>module2_actuator_prop1_joint</jointName>
      <linkName>module2_prop1_link</linkName>
      <turningDirection>ccw</turningDirection>
      <timeConstantUp>0.0125</timeConstantUp>
      <timeConstantDown>0.025</timeConstantDown>
      <maxRotVelocity>1500</maxRotVelocity>
      <motorConstant>2e-05</motorConstant>
      <momentConstant>0.06</momentConstant>
      <commandSubTopic>command/motor_speed</commandSubTopic>
      <motorNumber>2</motorNumber>
      <rotorDragCoefficient>0.000106428</rotorDragCoefficient>
      <rollingMomentCoefficient>1e-06</rollingMomentCoefficient>
      <rotorVelocitySlowdownSim>20</rotorVelocitySlowdownSim>
      <motorType>velocity</motorType>
    </plugin>
  </gazebo>
  <joint name="module2_actuator_prop2_joint" type="continuous">
    <origin rpy="0 0 0" xyz="0.0 0.0 -0.0781"/>
    <parent link="module2_actuator_link"/>
    <child link="module2_prop2_link"/>
    <axis xyz="0.0 0.0 -1.0"/>
    <limit effort="30000" lower="-1e+16" upper="1e+16" velocity="10000.0"/>
    <!-- <limit lower="-1e+16" upper="1e+16" /> -->
  </joint>
  <transmission name="revolute_module2_actuator_prop2_joint">
    <type>transmission_interface/SimpleTransmission</type>
    <joint name="module2_actuator_prop2_joint">
      <hardwareInterface>hardware_interface/EffortJointInterface</hardwareInterface>
    </joint>
    <actuator name="actuator_module2_actuator_prop2_joint">
      <hardwareInterface>hardware_interface/EffortJointInterface</hardwareInterface>
      <mechanicalReduction>1</mechanicalReduction>
    </actuator>
  </transmission>
  <gazebo>
    <plugin filename="gz-sim-multicopter-motor-model-system" name="gz::sim::systems::MulticopterMotorModel">
      <jointName>module2_actuator_prop2_joint</jointName>
      <linkName>module2_prop2_link</linkName>
      <turningDirection>ccw</turningDirection>
      <timeConstantUp>0.0125</timeConstantUp>
      <timeConstantDown>0.025</timeConstantDown>
      <maxRotVelocity>1500</maxRotVelocity>
      <motorConstant>2e-05</motorConstant>
      <momentConstant>0.06</momentConstant>
      <commandSubTopic>command/motor_speed</commandSubTopic>
      <motorNumber>3</motorNumber>
      <rotorDragCoefficient>0.000106428</rotorDragCoefficient>
      <rollingMomentCoefficient>1e-06</rollingMomentCoefficient>
      <rotorVelocitySlowdownSim>20</rotorVelocitySlowdownSim>
      <motorType>velocity</motorType>
    </plugin>
  </gazebo>
  <link name="module3_body_link">
    <inertial>
      <origin rpy="0 0 0" xyz="0.0 0.0 0.0"/>
      <mass value="0.50823179"/>
      <inertia ixx="0.01671968" ixy="-0.00001217" ixz="-0.00000326" iyy="0.00290137" iyz="-0.00003388" izz="0.01758533"/>
    </inertial>
    <visual>
      <origin rpy="0 0 0" xyz="0 0 0"/>
      <geometry>
        <mesh filename="package://tvmd/meshes/agent/base_link.stl" scale="0.001 0.001 0.001"/>
      </geometry>
      <material name="black"/>
    </visual>
    <!-- <collision>
      <origin xyz="0 0 0" rpy="0 0 0"/>
      <geometry>
        <mesh filename="package://tvmd/meshes/agent/base_link.stl" scale="0.001 0.001 0.001"/>
      </geometry>
    </collision> -->
    <velocity_decay/>
  </link>
  <gazebo reference="module3_body_link">
    <material>Gazebo/Black</material>
    <!-- Frictions -->
    <mu1>0.2</mu1>
    <mu2>0.2</mu2>
    <selfCollide>false</selfCollide>
    <gravity>true</gravity>
  </gazebo>
  <link name="module3_gimbal_link">
    <inertial>
      <origin rpy="0 0 0" xyz="0.0 0.0 0.0"/>
      <mass value="0.03395528"/>
      <inertia ixx="0.00034948" ixy="0.0" ixz="0.0" iyy="0.00000164" iyz="-0.00000002" izz="0.00034950"/>
    </inertial>
    <visual>
      <origin rpy="0 0 0" xyz="0.0 0.0 -0.068"/>
      <geometry>
        <mesh filename="package://tvmd/meshes/agent/Gimbal_Frame_1.stl" scale="0.001 0.001 0.001"/>
      </geometry>
      <material name="gray"/>
    </visual>
    <collision name="module3_actuator_collision">
      <origin rpy="1.5707963267948966 0 0" xyz="0 0 0"/>
      <geometry>
        <cylinder length="0.400" radius="0.010"/>
      </geometry>
    </collision>
  </link>
  <gazebo reference="module3_gimbal_link">
    <material>Gazebo/Gray</material>
    <!-- Frictions -->
    <mu1>0.2</mu1>
    <mu2>0.2</mu2>
    <selfCollide>false</selfCollide>
    <gravity>true</gravity>
  </gazebo>
  <link name="module3_actuator_link">
    <inertial>
      <origin rpy="0 0 0" xyz="0.0 0.0 0.0"/>
      <mass value="0.12540720"/>
      <inertia ixx="0.00029933" ixy="-0.00000011" ixz="-0.00000476" iyy="0.00030455" iyz="0.00000018" izz="0.00001575"/>
    </inertial>
    <visual>
      <origin rpy="0 0 0" xyz="0.0 0.0 -0.068"/>
      <geometry>
        <mesh filename="package://tvmd/meshes/agent/Actuator_1.stl" scale="0.001 0.001 0.001"/>
      </geometry>
      <material name="gray"/>
    </visual>
  </link>
  <gazebo reference="module3_actuator_link">
    <material>Gazebo/Gray</material>
    <!-- Frictions -->
    <mu1>0.2</mu1>
    <mu2>0.2</mu2>
    <selfCollide>false</selfCollide>
    <gravity>true</gravity>
  </gazebo>
  <link name="module3_prop1_link">
    <inertial>
      <origin rpy="0 0 0" xyz="0.0 0.0 0.0"/>
      <mass value="0.00253778"/>
      <inertia ixx="0.00000702" ixy="0.00000000" ixz="0.00000000" iyy="0.00000005" iyz="-0.00000009" izz="0.00000705"/>
    </inertial>
    <visual>
      <origin rpy="1.5707963267948966 0 0" xyz="0.0 0.0 0.0"/>
      <geometry>
        <mesh filename="package://tvmd/meshes/agent/Propeller_9047.stl" scale="0.001 0.001 0.001"/>
      </geometry>
      <material name="yellow"/>
    </visual>
    <collision name="module3_rotor_1_collision">
      <origin rpy="0 0 0" xyz="0 0 0"/>
      <geometry>
        <cylinder length="0.005" radius="0.12"/>
      </geometry>
    </collision>
  </link>
  <gazebo reference="module3_prop1_link">
    <material>Gazebo/Yellow</material>
    <!-- Frictions -->
    <mu1>0.2</mu1>
    <mu2>0.2</mu2>
    <selfCollide>false</selfCollide>
    <gravity>true</gravity>
  </gazebo>
  <link name="module3_prop2_link">
    <inertial>
      <origin rpy="0 0 0" xyz="0.0 0.0 0.0"/>
      <mass value="0.00253778"/>
      <inertia ixx="0.00000702" ixy="0.00000000" ixz="0.00000000" iyy="0.00000005" iyz="-0.00000009" izz="0.00000705"/>
    </inertial>
    <visual>
      <origin rpy="1.5707963267948966 0 0" xyz="0.0 0.0 0.0"/>
      <geometry>
        <mesh filename="package://tvmd/meshes/agent/Propeller_9047.stl" scale="0.001 0.001 0.001"/>
      </geometry>
      <material name="yellow"/>
    </visual>
    <collision name="module3_rotor_2_collision">
      <origin rpy="0 0 0" xyz="0 0 0"/>
      <geometry>
        <cylinder length="0.005" radius="0.12"/>
      </geometry>
    </collision>
  </link>
  <gazebo reference="module3_prop2_link">
    <material>Gazebo/Yellow</material>
    <!-- Frictions -->
    <mu1>0.2</mu1>
    <mu2>0.2</mu2>
    <selfCollide>false</selfCollide>
    <gravity>true</gravity>
  </gazebo>
  <joint name="module3_body_gimbal_joint" type="revolute">
    <origin rpy="0 0 0" xyz="0.0 0.0 0.068"/>
    <parent link="module3_body_link"/>
    <child link="module3_gimbal_link"/>
    <axis xyz="0.0 1.0 0.0"/>
    <limit effort="30000" lower="-1.5707963267948966" upper="1.5707963267948966" velocity="10.0"/>
    <dynamics damping="0.000"/>
    <physics>
      <ode implicit_spring_damper="0"/>
    </physics>
  </joint>
  <transmission name="revolute_module3_body_gimbal_joint">
    <type>transmission_interface/SimpleTransmission</type>
    <joint name="module3_body_gimbal_joint">
      <hardwareInterface>hardware_interface/EffortJointInterface</hardwareInterface>
    </joint>
    <actuator name="actuator_module3_body_gimbal_joint">
      <hardwareInterface>hardware_interface/EffortJointInterface</hardwareInterface>
      <mechanicalReduction>1</mechanicalReduction>
    </actuator>
  </transmission>
  <gazebo>
    <plugin filename="gz-sim-joint-position-controller-system" name="gz::sim::systems::JointPositionController">
      <joint_name>module3_body_gimbal_joint</joint_name>
      <sub_topic>servo_5</sub_topic>
      <!-- <topic>"/model/tvmd_0/servo_${joint_index}"</topic> -->
      <!-- <joint_index>"${joint_index}"</joint_index> -->
    </plugin>
  </gazebo>
  <joint name="module3_gimbal_actuator_joint" type="revolute">
    <origin rpy="0 0 0" xyz="0.0 0.0 0.0"/>
    <parent link="module3_gimbal_link"/>
    <child link="module3_actuator_link"/>
    <axis xyz="1.0 0.0 0.0"/>
    <limit effort="30000" lower="-0.5235987755982988" upper="0.5235987755982988" velocity="10.0"/>
    <dynamics damping="0.000"/>
    <physics>
      <ode implicit_spring_damper="0"/>
    </physics>
  </joint>
  <transmission name="revolute_module3_gimbal_actuator_joint">
    <type>transmission_interface/SimpleTransmission</type>
    <joint name="module3_gimbal_actuator_joint">
      <hardwareInterface>hardware_interface/EffortJointInterface</hardwareInterface>
    </joint>
    <actuator name="actuator_module3_gimbal_actuator_joint">
      <hardwareInterface>hardware_interface/EffortJointInterface</hardwareInterface>
      <mechanicalReduction>1</mechanicalReduction>
    </actuator>
  </transmission>
  <gazebo>
    <plugin filename="gz-sim-joint-position-controller-system" name="gz::sim::systems::JointPositionController">
      <joint_name>module3_gimbal_actuator_joint</joint_name>
      <sub_topic>servo_4</sub_topic>
      <!-- <topic>"/model/tvmd_0/servo_${joint_index}"</topic> -->
      <!-- <joint_index>"${joint_index}"</joint_index> -->
    </plugin>
  </gazebo>
  <joint name="module3_actuator_prop1_joint" type="continuous">
    <origin rpy="0 0 0" xyz="0.0 0.0 0.0781"/>
    <parent link="module3_actuator_link"/>
    <child link="module3_prop1_link"/>
    <axis xyz="0.0 0.0 1.0"/>
    <limit effort="30000" lower="-1e+16" upper="1e+16" velocity="10000.0"/>
    <!-- <limit lower="-1e+16" upper="1e+16" /> -->
  </joint>
  <transmission name="revolute_module3_actuator_prop1_joint">
    <type>transmission_interface/SimpleTransmission</type>
    <joint name="module3_actuator_prop1_joint">
      <hardwareInterface>hardware_interface/EffortJointInterface</hardwareInterface>
    </joint>
    <actuator name="actuator_module3_actuator_prop1_joint">
      <hardwareInterface>hardware_interface/EffortJointInterface</hardwareInterface>
      <mechanicalReduction>1</mechanicalReduction>
    </actuator>
  </transmission>
  <gazebo>
    <plugin filename="gz-sim-multicopter-motor-model-system" name="gz::sim::systems::MulticopterMotorModel">
      <jointName>module3_actuator_prop1_joint</jointName>
      <linkName>module3_prop1_link</linkName>
      <turningDirection>ccw</turningDirection>
      <timeConstantUp>0.0125</timeConstantUp>
      <timeConstantDown>0.025</timeConstantDown>
      <maxRotVelocity>1500</maxRotVelocity>
      <motorConstant>2e-05</motorConstant>
      <momentConstant>0.06</momentConstant>
      <commandSubTopic>command/motor_speed</commandSubTopic>
      <motorNumber>4</motorNumber>
      <rotorDragCoefficient>0.000106428</rotorDragCoefficient>
      <rollingMomentCoefficient>1e-06</rollingMomentCoefficient>
      <rotorVelocitySlowdownSim>20</rotorVelocitySlowdownSim>
      <motorType>velocity</motorType>
    </plugin>
  </gazebo>
  <joint name="module3_actuator_prop2_joint" type="continuous">
    <origin rpy="0 0 0" xyz="0.0 0.0 -0.0781"/>
    <parent link="module3_actuator_link"/>
    <child link="module3_prop2_link"/>
    <axis xyz="0.0 0.0 -1.0"/>
    <limit effort="30000" lower="-1e+16" upper="1e+16" velocity="10000.0"/>
    <!-- <limit lower="-1e+16" upper="1e+16" /> -->
  </joint>
  <transmission name="revolute_module3_actuator_prop2_joint">
    <type>transmission_interface/SimpleTransmission</type>
    <joint name="module3_actuator_prop2_joint">
      <hardwareInterface>hardware_interface/EffortJointInterface</hardwareInterface>
    </joint>
    <actuator name="actuator_module3_actuator_prop2_joint">
      <hardwareInterface>hardware_interface/EffortJointInterface</hardwareInterface>
      <mechanicalReduction>1</mechanicalReduction>
    </actuator>
  </transmission>
  <gazebo>
    <plugin filename="gz-sim-multicopter-motor-model-system" name="gz::sim::systems::MulticopterMotorModel">
      <jointName>module3_actuator_prop2_joint</jointName>
      <linkName>module3_prop2_link</linkName>
      <turningDirection>ccw</turningDirection>
      <timeConstantUp>0.0125</timeConstantUp>
      <timeConstantDown>0.025</timeConstantDown>
      <maxRotVelocity>1500</maxRotVelocity>
      <motorConstant>2e-05</motorConstant>
      <momentConstant>0.06</momentConstant>
      <commandSubTopic>command/motor_speed</commandSubTopic>
      <motorNumber>5</motorNumber>
      <rotorDragCoefficient>0.000106428</rotorDragCoefficient>
      <rollingMomentCoefficient>1e-06</rollingMomentCoefficient>
      <rotorVelocitySlowdownSim>20</rotorVelocitySlowdownSim>
      <motorType>velocity</motorType>
    </plugin>
  </gazebo>
  <link name="module4_body_link">
    <inertial>
      <origin rpy="0 0 0" xyz="0.0 0.0 0.0"/>
      <mass value="0.50823179"/>
      <inertia ixx="0.01671968" ixy="-0.00001217" ixz="-0.00000326" iyy="0.00290137" iyz="-0.00003388" izz="0.01758533"/>
    </inertial>
    <visual>
      <origin rpy="0 0 0" xyz="0 0 0"/>
      <geometry>
        <mesh filename="package://tvmd/meshes/agent/base_link.stl" scale="0.001 0.001 0.001"/>
      </geometry>
      <material name="black"/>
    </visual>
    <!-- <collision>
      <origin xyz="0 0 0" rpy="0 0 0"/>
      <geometry>
        <mesh filename="package://tvmd/meshes/agent/base_link.stl" scale="0.001 0.001 0.001"/>
      </geometry>
    </collision> -->
    <velocity_decay/>
  </link>
  <gazebo reference="module4_body_link">
    <material>Gazebo/Black</material>
    <!-- Frictions -->
    <mu1>0.2</mu1>
    <mu2>0.2</mu2>
    <selfCollide>false</selfCollide>
    <gravity>true</gravity>
  </gazebo>
  <link name="module4_gimbal_link">
    <inertial>
      <origin rpy="0 0 0" xyz="0.0 0.0 0.0"/>
      <mass value="0.03395528"/>
      <inertia ixx="0.00034948" ixy="0.0" ixz="0.0" iyy="0.00000164" iyz="-0.00000002" izz="0.00034950"/>
    </inertial>
    <visual>
      <origin rpy="0 0 0" xyz="0.0 0.0 -0.068"/>
      <geometry>
        <mesh filename="package://tvmd/meshes/agent/Gimbal_Frame_1.stl" scale="0.001 0.001 0.001"/>
      </geometry>
      <material name="gray"/>
    </visual>
    <collision name="module4_actuator_collision">
      <origin rpy="1.5707963267948966 0 0" xyz="0 0 0"/>
      <geometry>
        <cylinder length="0.400" radius="0.010"/>
      </geometry>
    </collision>
  </link>
  <gazebo reference="module4_gimbal_link">
    <material>Gazebo/Gray</material>
    <!-- Frictions -->
    <mu1>0.2</mu1>
    <mu2>0.2</mu2>
    <selfCollide>false</selfCollide>
    <gravity>true</gravity>
  </gazebo>
  <link name="module4_actuator_link">
    <inertial>
      <origin rpy="0 0 0" xyz="0.0 0.0 0.0"/>
      <mass value="0.12540720"/>
      <inertia ixx="0.00029933" ixy="-0.00000011" ixz="-0.00000476" iyy="0.00030455" iyz="0.00000018" izz="0.00001575"/>
    </inertial>
    <visual>
      <origin rpy="0 0 0" xyz="0.0 0.0 -0.068"/>
      <geometry>
        <mesh filename="package://tvmd/meshes/agent/Actuator_1.stl" scale="0.001 0.001 0.001"/>
      </geometry>
      <material name="gray"/>
    </visual>
  </link>
  <gazebo reference="module4_actuator_link">
    <material>Gazebo/Gray</material>
    <!-- Frictions -->
    <mu1>0.2</mu1>
    <mu2>0.2</mu2>
    <selfCollide>false</selfCollide>
    <gravity>true</gravity>
  </gazebo>
  <link name="module4_prop1_link">
    <inertial>
      <origin rpy="0 0 0" xyz="0.0 0.0 0.0"/>
      <mass value="0.00253778"/>
      <inertia ixx="0.00000702" ixy="0.00000000" ixz="0.00000000" iyy="0.00000005" iyz="-0.00000009" izz="0.00000705"/>
    </inertial>
    <visual>
      <origin rpy="1.5707963267948966 0 0" xyz="0.0 0.0 0.0"/>
      <geometry>
        <mesh filename="package://tvmd/meshes/agent/Propeller_9047.stl" scale="0.001 0.001 0.001"/>
      </geometry>
      <material name="yellow"/>
    </visual>
    <collision name="module4_rotor_1_collision">
      <origin rpy="0 0 0" xyz="0 0 0"/>
      <geometry>
        <cylinder length="0.005" radius="0.12"/>
      </geometry>
    </collision>
  </link>
  <gazebo reference="module4_prop1_link">
    <material>Gazebo/Yellow</material>
    <!-- Frictions -->
    <mu1>0.2</mu1>
    <mu2>0.2</mu2>
    <selfCollide>false</selfCollide>
    <gravity>true</gravity>
  </gazebo>
  <link name="module4_prop2_link">
    <inertial>
      <origin rpy="0 0 0" xyz="0.0 0.0 0.0"/>
      <mass value="0.00253778"/>
      <inertia ixx="0.00000702" ixy="0.00000000" ixz="0.00000000" iyy="0.00000005" iyz="-0.00000009" izz="0.00000705"/>
    </inertial>
    <visual>
      <origin rpy="1.5707963267948966 0 0" xyz="0.0 0.0 0.0"/>
      <geometry>
        <mesh filename="package://tvmd/meshes/agent/Propeller_9047.stl" scale="0.001 0.001 0.001"/>
      </geometry>
      <material name="yellow"/>
    </visual>
    <collision name="module4_rotor_2_collision">
      <origin rpy="0 0 0" xyz="0 0 0"/>
      <geometry>
        <cylinder length="0.005" radius="0.12"/>
      </geometry>
    </collision>
  </link>
  <gazebo reference="module4_prop2_link">
    <material>Gazebo/Yellow</material>
    <!-- Frictions -->
    <mu1>0.2</mu1>
    <mu2>0.2</mu2>
    <selfCollide>false</selfCollide>
    <gravity>true</gravity>
  </gazebo>
  <joint name="module4_body_gimbal_joint" type="revolute">
    <origin rpy="0 0 0" xyz="0.0 0.0 0.068"/>
    <parent link="module4_body_link"/>
    <child link="module4_gimbal_link"/>
    <axis xyz="0.0 1.0 0.0"/>
    <limit effort="30000" lower="-1.5707963267948966" upper="1.5707963267948966" velocity="10.0"/>
    <dynamics damping="0.000"/>
    <physics>
      <ode implicit_spring_damper="0"/>
    </physics>
  </joint>
  <transmission name="revolute_module4_body_gimbal_joint">
    <type>transmission_interface/SimpleTransmission</type>
    <joint name="module4_body_gimbal_joint">
      <hardwareInterface>hardware_interface/EffortJointInterface</hardwareInterface>
    </joint>
    <actuator name="actuator_module4_body_gimbal_joint">
      <hardwareInterface>hardware_interface/EffortJointInterface</hardwareInterface>
      <mechanicalReduction>1</mechanicalReduction>
    </actuator>
  </transmission>
  <gazebo>
    <plugin filename="gz-sim-joint-position-controller-system" name="gz::sim::systems::JointPositionController">
      <joint_name>module4_body_gimbal_joint</joint_name>
      <sub_topic>servo_7</sub_topic>
      <!-- <topic>"/model/tvmd_0/servo_${joint_index}"</topic> -->
      <!-- <joint_index>"${joint_index}"</joint_index> -->
    </plugin>
  </gazebo>
  <joint name="module4_gimbal_actuator_joint" type="revolute">
    <origin rpy="0 0 0" xyz="0.0 0.0 0.0"/>
    <parent link="module4_gimbal_link"/>
    <child link="module4_actuator_link"/>
    <axis xyz="1.0 0.0 0.0"/>
    <limit effort="30000" lower="-0.5235987755982988" upper="0.5235987755982988" velocity="10.0"/>
    <dynamics damping="0.000"/>
    <physics>
      <ode implicit_spring_damper="0"/>
    </physics>
  </joint>
  <transmission name="revolute_module4_gimbal_actuator_joint">
    <type>transmission_interface/SimpleTransmission</type>
    <joint name="module4_gimbal_actuator_joint">
      <hardwareInterface>hardware_interface/EffortJointInterface</hardwareInterface>
    </joint>
    <actuator name="actuator_module4_gimbal_actuator_joint">
      <hardwareInterface>hardware_interface/EffortJointInterface</hardwareInterface>
      <mechanicalReduction>1</mechanicalReduction>
    </actuator>
  </transmission>
  <gazebo>
    <plugin filename="gz-sim-joint-position-controller-system" name="gz::sim::systems::JointPositionController">
      <joint_name>module4_gimbal_actuator_joint</joint_name>
      <sub_topic>servo_6</sub_topic>
      <!-- <topic>"/model/tvmd_0/servo_${joint_index}"</topic> -->
      <!-- <joint_index>"${joint_index}"</joint_index> -->
    </plugin>
  </gazebo>
  <joint name="module4_actuator_prop1_joint" type="continuous">
    <origin rpy="0 0 0" xyz="0.0 0.0 0.0781"/>
    <parent link="module4_actuator_link"/>
    <child link="module4_prop1_link"/>
    <axis xyz="0.0 0.0 1.0"/>
    <limit effort="30000" lower="-1e+16" upper="1e+16" velocity="10000.0"/>
    <!-- <limit lower="-1e+16" upper="1e+16" /> -->
  </joint>
  <transmission name="revolute_module4_actuator_prop1_joint">
    <type>transmission_interface/SimpleTransmission</type>
    <joint name="module4_actuator_prop1_joint">
      <hardwareInterface>hardware_interface/EffortJointInterface</hardwareInterface>
    </joint>
    <actuator name="actuator_module4_actuator_prop1_joint">
      <hardwareInterface>hardware_interface/EffortJointInterface</hardwareInterface>
      <mechanicalReduction>1</mechanicalReduction>
    </actuator>
  </transmission>
  <gazebo>
    <plugin filename="gz-sim-multicopter-motor-model-system" name="gz::sim::systems::MulticopterMotorModel">
      <jointName>module4_actuator_prop1_joint</jointName>
      <linkName>module4_prop1_link</linkName>
      <turningDirection>ccw</turningDirection>
      <timeConstantUp>0.0125</timeConstantUp>
      <timeConstantDown>0.025</timeConstantDown>
      <maxRotVelocity>1500</maxRotVelocity>
      <motorConstant>2e-05</motorConstant>
      <momentConstant>0.06</momentConstant>
      <commandSubTopic>command/motor_speed</commandSubTopic>
      <motorNumber>6</motorNumber>
      <rotorDragCoefficient>0.000106428</rotorDragCoefficient>
      <rollingMomentCoefficient>1e-06</rollingMomentCoefficient>
      <rotorVelocitySlowdownSim>20</rotorVelocitySlowdownSim>
      <motorType>velocity</motorType>
    </plugin>
  </gazebo>
  <joint name="module4_actuator_prop2_joint" type="continuous">
    <origin rpy="0 0 0" xyz="0.0 0.0 -0.0781"/>
    <parent link="module4_actuator_link"/>
    <child link="module4_prop2_link"/>
    <axis xyz="0.0 0.0 -1.0"/>
    <limit effort="30000" lower="-1e+16" upper="1e+16" velocity="10000.0"/>
    <!-- <limit lower="-1e+16" upper="1e+16" /> -->
  </joint>
  <transmission name="revolute_module4_actuator_prop2_joint">
    <type>transmission_interface/SimpleTransmission</type>
    <joint name="module4_actuator_prop2_joint">
      <hardwareInterface>hardware_interface/EffortJointInterface</hardwareInterface>
    </joint>
    <actuator name="actuator_module4_actuator_prop2_joint">
      <hardwareInterface>hardware_interface/EffortJointInterface</hardwareInterface>
      <mechanicalReduction>1</mechanicalReduction>
    </actuator>
  </transmission>
  <gazebo>
    <plugin filename="gz-sim-multicopter-motor-model-system" name="gz::sim::systems::MulticopterMotorModel">
      <jointName>module4_actuator_prop2_joint</jointName>
      <linkName>module4_prop2_link</linkName>
      <turningDirection>ccw</turningDirection>
      <timeConstantUp>0.0125</timeConstantUp>
      <timeConstantDown>0.025</timeConstantDown>
      <maxRotVelocity>1500</maxRotVelocity>
      <motorConstant>2e-05</motorConstant>
      <momentConstant>0.06</momentConstant>
      <commandSubTopic>command/motor_speed</commandSubTopic>
      <motorNumber>7</motorNumber>
      <rotorDragCoefficient>0.000106428</rotorDragCoefficient>
      <rollingMomentCoefficient>1e-06</rollingMomentCoefficient>
      <rotorVelocitySlowdownSim>20</rotorVelocitySlowdownSim>
      <motorType>velocity</motorType>
    </plugin>
  </gazebo>
  <joint name="rigid_base_link_module1_body_link" type="fixed">
    <origin rpy="0 0 1.5707963267948966" xyz="0.215 0.215 0.0"/>
    <parent link="base_link"/>
    <child link="module1_body_link"/>
  </joint>
  <joint name="rigid_base_link_module2_body_link" type="fixed">
    <origin rpy="0 0 1.5707963267948966" xyz="0.215 -0.215 0.0"/>
    <parent link="base_link"/>
    <child link="module2_body_link"/>
  </joint>
  <joint name="rigid_base_link_module3_body_link" type="fixed">
    <origin rpy="0 0 0" xyz="-0.215 0.215 0.0"/>
    <parent link="base_link"/>
    <child link="module3_body_link"/>
  </joint>
  <joint name="rigid_base_link_module4_body_link" type="fixed">
    <origin rpy="0 0 0" xyz="-0.215 -0.215 0.0"/>
    <parent link="base_link"/>
    <child link="module4_body_link"/>
  </joint>
  <!-- <static>0</static> -->
</robot>

