<?xml version="1.0" ?>
<robot name="tvmd" xmlns:xacro="http://www.ros.org/wiki/xacro">

<!-- Define Module Macros -->

<!-- Links -->

<xacro:macro name="body_link" params="module_id">
  <link name="module${module_id}_body_link">
    <inertial>
      <origin xyz="0.0 0.0 0.0" rpy="0 0 0"/>
      <mass value="0.50823179"/>
      <inertia ixx="0.01671968" iyy="0.00290137" izz="0.01758533" ixy="-0.00001217" iyz="-0.00003388" ixz="-0.00000326"/>
    </inertial>
    <visual>
      <origin xyz="0 0 0" rpy="0 0 0"/>
      <geometry>
        <mesh filename="package://tvmd/meshes/agent/base_link.stl" scale="0.001 0.001 0.001"/>
      </geometry>
      <material name="black"/>
    </visual>
    <!-- <collision>
      <origin xyz="0 0 0" rpy="0 0 0"/>
      <geometry>
        <mesh filename="package://tvmd/meshes/agent/base_link.stl" scale="0.001 0.001 0.001"/>
      </geometry>
    </collision> -->

    <velocity_decay/>
  </link>

  <xacro:gz_material joint_name="module${module_id}_body_link" color_name="Black" />
</xacro:macro>

<xacro:macro name="gimbal_link" params="module_id">
  <link name="module${module_id}_gimbal_link">
    <inertial>
      <origin xyz="0.0 0.0 0.0" rpy="0 0 0"/>
        <mass value="0.03395528"/>
        <inertia ixx="0.00034948" iyy="0.00000164" izz="0.00034950" ixy="0.0" iyz="-0.00000002" ixz="0.0"/>
    </inertial>
    <visual>
      <origin xyz="0.0 0.0 -0.068" rpy="0 0 0"/>
      <geometry>
        <mesh filename="package://tvmd/meshes/agent/Gimbal_Frame_1.stl" scale="0.001 0.001 0.001"/>
      </geometry>
      <material name="gray"/>
    </visual>
    <collision name='module${module_id}_actuator_collision'>
      <origin xyz="0 0 0" rpy="${pi/2} 0 0"/>
      <geometry>
        <cylinder length="0.400" radius="0.010"/>
      </geometry>
    </collision>
  </link>

  <xacro:gz_material joint_name="module${module_id}_gimbal_link" color_name="Gray" />
</xacro:macro>

<xacro:macro name="actuator_link" params="module_id">
  <link name="module${module_id}_actuator_link">
    <inertial>
      <origin xyz="0.0 0.0 0.0" rpy="0 0 0"/>
        <mass value="0.12540720"/>
        <inertia ixx="0.00029933" iyy="0.00030455" izz="0.00001575" ixy="-0.00000011" iyz="0.00000018" ixz="-0.00000476"/>
    </inertial>
    <visual>
      <origin xyz="0.0 0.0 -0.068" rpy="0 0 0"/>
      <geometry>
        <mesh filename="package://tvmd/meshes/agent/Actuator_1.stl" scale="0.001 0.001 0.001"/>
      </geometry>
      <material name="gray"/>
    </visual>
  </link>

  <xacro:gz_material joint_name="module${module_id}_actuator_link" color_name="Gray" />
</xacro:macro>

<xacro:macro name="prop1_link" params="module_id">
  <link name="module${module_id}_prop1_link">
    <inertial>
      <origin xyz="0.0 0.0 0.0" rpy="0 0 0"/>
        <mass value="0.00253778"/>
        <inertia ixx="0.00000702" iyy="0.00000005" izz="0.00000705" ixy="0.00000000" iyz="-0.00000009" ixz="0.00000000"/>
    </inertial>
    <visual>
      <origin xyz="0.0 0.0 0.0" rpy="${pi/2} 0 0"/>
      <geometry>
        <mesh filename="package://tvmd/meshes/agent/Propeller_9047.stl" scale="0.001 0.001 0.001"/>
      </geometry>
      <material name="yellow"/>
    </visual>
    <collision name='module${module_id}_rotor_1_collision'>
      <origin xyz="0 0 0" rpy="0 0 0"/>
      <geometry>
        <cylinder length="0.005" radius="0.12"/>
      </geometry>
    </collision>
  </link>

  <xacro:gz_material joint_name="module${module_id}_prop1_link" color_name="Yellow" />
</xacro:macro>

<xacro:macro name="prop2_link" params="module_id">
  <link name="module${module_id}_prop2_link">
    <inertial>
      <origin xyz="0.0 0.0 0.0" rpy="0 0 0"/>
      <mass value="0.00253778"/>
      <inertia ixx="0.00000702" iyy="0.00000005" izz="0.00000705" ixy="0.00000000" iyz="-0.00000009" ixz="0.00000000"/>
    </inertial>
    <visual>
      <origin xyz="0.0 0.0 0.0" rpy="${pi/2} 0 0"/>
      <geometry>
        <mesh filename="package://tvmd/meshes/agent/Propeller_9047.stl" scale="0.001 0.001 0.001"/>
      </geometry>
      <material name="yellow"/>
    </visual>
    <collision name='module${module_id}_rotor_2_collision'>
      <origin xyz="0 0 0" rpy="0 0 0"/>
      <geometry>
        <cylinder length="0.005" radius="0.12"/>
      </geometry>
    </collision>
  </link>

  <xacro:gz_material joint_name="module${module_id}_prop2_link" color_name="Yellow" />
</xacro:macro>

<!-- Joints -->

<!-- Y-Servo -->
<xacro:macro name="body_gimbal_joint" params="module_id">
  <joint name="module${module_id}_body_gimbal_joint" type="revolute">
    <origin xyz="0.0 0.0 0.068" rpy="0 0 0"/>
    <parent link="module${module_id}_body_link"/>
    <child link="module${module_id}_gimbal_link"/>
    <axis xyz="0.0 1.0 0.0"/>
    <!-- <limit effort="30000" velocity="10.0" lower="${-pi/2}" upper="${pi/2}" /> -->
    <limit effort="30000" velocity="10.0" lower="${-pi/4}" upper="${pi/4}" />
    <dynamics damping="0.000" />
    <physics>
      <ode implicit_spring_damper="0" />
    </physics>
  </joint>
    
  <xacro:simple_transmission joint_name="module${module_id}_body_gimbal_joint" />

  <xacro:gz_servo joint_name="module${module_id}_body_gimbal_joint" 
    sub_topic="servo_${module_id*2-1}" />
</xacro:macro>

<!-- X-Servo -->
<xacro:macro name="gimbal_actuator_joint" params="module_id">
  <joint name="module${module_id}_gimbal_actuator_joint" type="revolute">
    <origin xyz="0.0 0.0 0.0" rpy="0 0 0"/>
    <parent link="module${module_id}_gimbal_link"/>
    <child link="module${module_id}_actuator_link"/>
    <axis xyz="1.0 0.0 0.0"/>
    <!-- <limit effort="30000" velocity="10.0" lower="${-pi/6}" upper="${pi/6}" /> -->
    <limit effort="30000" velocity="10.0" lower="-0.349" upper="0.349" />
    <dynamics damping="0.000" />
    <physics>
      <ode implicit_spring_damper="0" />
    </physics>
  </joint>

  <xacro:simple_transmission joint_name="module${module_id}_gimbal_actuator_joint" />

  <xacro:gz_servo joint_name="module${module_id}_gimbal_actuator_joint" 
    sub_topic="servo_${module_id*2-2}" />
</xacro:macro>

<!-- Propellers -->
<xacro:macro name="actuator_prop1_joint" params="module_id">
  <joint name="module${module_id}_actuator_prop1_joint" type="continuous">
    <origin xyz="0.0 0.0 0.0781" rpy="0 0 0"/>
    <parent link="module${module_id}_actuator_link"/>
    <child link="module${module_id}_prop1_link"/>
    <axis xyz="0.0 0.0 1.0"/>
    <limit effort="30000" velocity="10000.0" lower="-1e+16" upper="1e+16" />
    <!-- <limit lower="-1e+16" upper="1e+16" /> -->
  </joint>

  <xacro:simple_transmission joint_name="module${module_id}_actuator_prop1_joint" />

  <xacro:gz_prop joint_name="module${module_id}_actuator_prop1_joint" 
    link_name="module${module_id}_prop1_link"
    number_motor="${module_id*2-2}"/>
</xacro:macro>

<xacro:macro name="actuator_prop2_joint" params="module_id">
  <joint name="module${module_id}_actuator_prop2_joint" type="continuous">
    <origin xyz="0.0 0.0 -0.0781" rpy="0 0 0"/>
    <parent link="module${module_id}_actuator_link"/>
    <child link="module${module_id}_prop2_link"/>
    <axis xyz="0.0 0.0 -1.0"/>
    <limit effort="30000" velocity="10000.0" lower="-1e+16" upper="1e+16" />
    <!-- <limit lower="-1e+16" upper="1e+16" /> -->
  </joint>

  <xacro:simple_transmission joint_name="module${module_id}_actuator_prop2_joint" />

  <xacro:gz_prop joint_name="module${module_id}_actuator_prop2_joint" 
    link_name="module${module_id}_prop2_link"
    number_motor="${module_id*2-1}"/>
</xacro:macro>

</robot>